{"level":"ERROR","location":"[<lambda>:1663] data_ws","message":"Connection to remote host was lost.","timestamp":"2025-06-10 11:45:56,369+0530","service":"FyersDataSocket"}
{"level":"ERROR","location":"[<lambda>:1663] data_ws","message":"Connection to remote host was lost.","timestamp":"2025-06-10 12:40:29,161+0530","service":"FyersDataSocket"}
{"level":"ERROR","location":"[<lambda>:1663] data_ws","message":"Connection to remote host was lost.","timestamp":"2025-06-10 12:42:19,653+0530","service":"FyersDataSocket"}
{"level":"ERROR","location":"[<lambda>:1663] data_ws","message":"Connection to remote host was lost.","timestamp":"2025-06-10 14:32:09,392+0530","service":"FyersDataSocket"}
{"level":"ERROR","location":"[<lambda>:1663] data_ws","message":"Connection to remote host was lost.","timestamp":"2025-06-10 14:34:31,941+0530","service":"FyersDataSocket"}
{"level":"ERROR","location":"[<lambda>:1663] data_ws","message":"Connection to remote host was lost.","timestamp":"2025-06-10 15:57:40,356+0530","service":"FyersDataSocket"}
{"level":"ERROR","location":"[<lambda>:1663] data_ws","message":"Connection to remote host was lost.","timestamp":"2025-06-11 09:14:21,205+0530","service":"FyersDataSocket"}
{"level":"ERROR","location":"[<lambda>:1663] data_ws","message":"Connection to remote host was lost.","timestamp":"2025-06-11 09:20:35,853+0530","service":"FyersDataSocket"}
{"level":"ERROR","location":"[<lambda>:1663] data_ws","message":"Connection to remote host was lost.","timestamp":"2025-06-11 10:04:42,456+0530","service":"FyersDataSocket"}
{"level":"ERROR","location":"[<lambda>:1663] data_ws","message":"Connection to remote host was lost.","timestamp":"2025-06-11 12:30:09,632+0530","service":"FyersDataSocket"}
{"level":"ERROR","location":"[<lambda>:1663] data_ws","message":"Connection to remote host was lost.","timestamp":"2025-06-11 12:31:38,698+0530","service":"FyersDataSocket"}
{"level":"ERROR","location":"[<lambda>:1663] data_ws","message":"Connection to remote host was lost.","timestamp":"2025-06-11 14:14:20,468+0530","service":"FyersDataSocket"}
{"level":"ERROR","location":"[<lambda>:1663] data_ws","message":"Connection to remote host was lost.","timestamp":"2025-06-11 14:18:05,104+0530","service":"FyersDataSocket"}
{"level":"ERROR","location":"[<lambda>:1663] data_ws","message":"[Errno 11001] getaddrinfo failed","timestamp":"2025-06-11 14:18:22,178+0530","service":"FyersDataSocket"}
{"level":"ERROR","location":"[exception:108] fyers_logger","message":"HTTPSConnectionPool(host='api-t1.fyers.in', port=443): Max retries exceeded with url: /data/symbol-token (Caused by NameResolutionError(\"<urllib3.connection.HTTPSConnection object at 0x000002117FAFE980>: Failed to resolve 'api-t1.fyers.in' ([Errno 11001] getaddrinfo failed)\"))","timestamp":"2025-06-11 14:18:24,187+0530","service":"FyersDataSocket","exception":"Traceback (most recent call last):\n  File \"C:\\Users\\eldoj\\PycharmProjects\\MARK6_V2.0\\.venv\\lib\\site-packages\\websocket\\_app.py\", line 428, in setSock\n    dispatcher.read(self.sock.sock, read, check)\n  File \"C:\\Users\\eldoj\\PycharmProjects\\MARK6_V2.0\\.venv\\lib\\site-packages\\websocket\\_app.py\", line 99, in read\n    if not read_callback():\n  File \"C:\\Users\\eldoj\\PycharmProjects\\MARK6_V2.0\\.venv\\lib\\site-packages\\websocket\\_app.py\", line 442, in read\n    raise e\n  File \"C:\\Users\\eldoj\\PycharmProjects\\MARK6_V2.0\\.venv\\lib\\site-packages\\websocket\\_app.py\", line 437, in read\n    op_code, frame = self.sock.recv_data_frame(True)\n  File \"C:\\Users\\eldoj\\PycharmProjects\\MARK6_V2.0\\.venv\\lib\\site-packages\\websocket\\_core.py\", line 406, in recv_data_frame\n    frame = self.recv_frame()\n  File \"C:\\Users\\eldoj\\PycharmProjects\\MARK6_V2.0\\.venv\\lib\\site-packages\\websocket\\_core.py\", line 445, in recv_frame\n    return self.frame_buffer.recv_frame()\n  File \"C:\\Users\\eldoj\\PycharmProjects\\MARK6_V2.0\\.venv\\lib\\site-packages\\websocket\\_abnf.py\", line 338, in recv_frame\n    self.recv_header()\n  File \"C:\\Users\\eldoj\\PycharmProjects\\MARK6_V2.0\\.venv\\lib\\site-packages\\websocket\\_abnf.py\", line 294, in recv_header\n    header = self.recv_strict(2)\n  File \"C:\\Users\\eldoj\\PycharmProjects\\MARK6_V2.0\\.venv\\lib\\site-packages\\websocket\\_abnf.py\", line 373, in recv_strict\n    bytes_ = self.recv(min(16384, shortage))\n  File \"C:\\Users\\eldoj\\PycharmProjects\\MARK6_V2.0\\.venv\\lib\\site-packages\\websocket\\_core.py\", line 529, in _recv\n    return recv(self.sock, bufsize)\n  File \"C:\\Users\\eldoj\\PycharmProjects\\MARK6_V2.0\\.venv\\lib\\site-packages\\websocket\\_socket.py\", line 122, in recv\n    raise WebSocketConnectionClosedException(\nwebsocket._exceptions.WebSocketConnectionClosedException: Connection to remote host was lost.\n\nDuring handling of the above exception, another exception occurred:\n\nTraceback (most recent call last):\n  File \"C:\\Users\\eldoj\\PycharmProjects\\MARK6_V2.0\\.venv\\lib\\site-packages\\urllib3\\connection.py\", line 198, in _new_conn\n    sock = connection.create_connection(\n  File \"C:\\Users\\eldoj\\PycharmProjects\\MARK6_V2.0\\.venv\\lib\\site-packages\\urllib3\\util\\connection.py\", line 60, in create_connection\n    for res in socket.getaddrinfo(host, port, family, socket.SOCK_STREAM):\n  File \"C:\\Users\\eldoj\\AppData\\Local\\Programs\\Python\\Python310\\lib\\socket.py\", line 955, in getaddrinfo\n    for res in _socket.getaddrinfo(host, port, family, type, proto, flags):\nsocket.gaierror: [Errno 11001] getaddrinfo failed\n\nThe above exception was the direct cause of the following exception:\n\nTraceback (most recent call last):\n  File \"C:\\Users\\eldoj\\PycharmProjects\\MARK6_V2.0\\.venv\\lib\\site-packages\\urllib3\\connectionpool.py\", line 787, in urlopen\n    response = self._make_request(\n  File \"C:\\Users\\eldoj\\PycharmProjects\\MARK6_V2.0\\.venv\\lib\\site-packages\\urllib3\\connectionpool.py\", line 488, in _make_request\n    raise new_e\n  File \"C:\\Users\\eldoj\\PycharmProjects\\MARK6_V2.0\\.venv\\lib\\site-packages\\urllib3\\connectionpool.py\", line 464, in _make_request\n    self._validate_conn(conn)\n  File \"C:\\Users\\eldoj\\PycharmProjects\\MARK6_V2.0\\.venv\\lib\\site-packages\\urllib3\\connectionpool.py\", line 1093, in _validate_conn\n    conn.connect()\n  File \"C:\\Users\\eldoj\\PycharmProjects\\MARK6_V2.0\\.venv\\lib\\site-packages\\urllib3\\connection.py\", line 704, in connect\n    self.sock = sock = self._new_conn()\n  File \"C:\\Users\\eldoj\\PycharmProjects\\MARK6_V2.0\\.venv\\lib\\site-packages\\urllib3\\connection.py\", line 205, in _new_conn\n    raise NameResolutionError(self.host, self, e) from e\nurllib3.exceptions.NameResolutionError: <urllib3.connection.HTTPSConnection object at 0x000002117FAFE980>: Failed to resolve 'api-t1.fyers.in' ([Errno 11001] getaddrinfo failed)\n\nThe above exception was the direct cause of the following exception:\n\nTraceback (most recent call last):\n  File \"C:\\Users\\eldoj\\PycharmProjects\\MARK6_V2.0\\.venv\\lib\\site-packages\\requests\\adapters.py\", line 486, in send\n    resp = conn.urlopen(\n  File \"C:\\Users\\eldoj\\PycharmProjects\\MARK6_V2.0\\.venv\\lib\\site-packages\\urllib3\\connectionpool.py\", line 841, in urlopen\n    retries = retries.increment(\n  File \"C:\\Users\\eldoj\\PycharmProjects\\MARK6_V2.0\\.venv\\lib\\site-packages\\urllib3\\util\\retry.py\", line 519, in increment\n    raise MaxRetryError(_pool, url, reason) from reason  # type: ignore[arg-type]\nurllib3.exceptions.MaxRetryError: HTTPSConnectionPool(host='api-t1.fyers.in', port=443): Max retries exceeded with url: /data/symbol-token (Caused by NameResolutionError(\"<urllib3.connection.HTTPSConnection object at 0x000002117FAFE980>: Failed to resolve 'api-t1.fyers.in' ([Errno 11001] getaddrinfo failed)\"))\n\nDuring handling of the above exception, another exception occurred:\n\nTraceback (most recent call last):\n  File \"C:\\Users\\eldoj\\PycharmProjects\\MARK6_V2.0\\.venv\\lib\\site-packages\\fyers_apiv3\\FyersWebsocket\\data_ws.py\", line 63, in symbol_to_hsmtoken\n    response = requests.post(\n  File \"C:\\Users\\eldoj\\PycharmProjects\\MARK6_V2.0\\.venv\\lib\\site-packages\\requests\\api.py\", line 115, in post\n    return request(\"post\", url, data=data, json=json, **kwargs)\n  File \"C:\\Users\\eldoj\\PycharmProjects\\MARK6_V2.0\\.venv\\lib\\site-packages\\requests\\api.py\", line 59, in request\n    return session.request(method=method, url=url, **kwargs)\n  File \"C:\\Users\\eldoj\\PycharmProjects\\MARK6_V2.0\\.venv\\lib\\site-packages\\requests\\sessions.py\", line 589, in request\n    resp = self.send(prep, **send_kwargs)\n  File \"C:\\Users\\eldoj\\PycharmProjects\\MARK6_V2.0\\.venv\\lib\\site-packages\\requests\\sessions.py\", line 703, in send\n    r = adapter.send(request, **kwargs)\n  File \"C:\\Users\\eldoj\\PycharmProjects\\MARK6_V2.0\\.venv\\lib\\site-packages\\requests\\adapters.py\", line 519, in send\n    raise ConnectionError(e, request=request)\nrequests.exceptions.ConnectionError: HTTPSConnectionPool(host='api-t1.fyers.in', port=443): Max retries exceeded with url: /data/symbol-token (Caused by NameResolutionError(\"<urllib3.connection.HTTPSConnection object at 0x000002117FAFE980>: Failed to resolve 'api-t1.fyers.in' ([Errno 11001] getaddrinfo failed)\"))","exception_name":"ConnectionError"}
{"level":"ERROR","location":"[exception:108] fyers_logger","message":"'NoneType' object is not subscriptable","timestamp":"2025-06-11 14:18:24,242+0530","service":"FyersDataSocket","exception":"Traceback (most recent call last):\n  File \"C:\\Users\\eldoj\\PycharmProjects\\MARK6_V2.0\\.venv\\lib\\site-packages\\websocket\\_app.py\", line 428, in setSock\n    dispatcher.read(self.sock.sock, read, check)\n  File \"C:\\Users\\eldoj\\PycharmProjects\\MARK6_V2.0\\.venv\\lib\\site-packages\\websocket\\_app.py\", line 99, in read\n    if not read_callback():\n  File \"C:\\Users\\eldoj\\PycharmProjects\\MARK6_V2.0\\.venv\\lib\\site-packages\\websocket\\_app.py\", line 442, in read\n    raise e\n  File \"C:\\Users\\eldoj\\PycharmProjects\\MARK6_V2.0\\.venv\\lib\\site-packages\\websocket\\_app.py\", line 437, in read\n    op_code, frame = self.sock.recv_data_frame(True)\n  File \"C:\\Users\\eldoj\\PycharmProjects\\MARK6_V2.0\\.venv\\lib\\site-packages\\websocket\\_core.py\", line 406, in recv_data_frame\n    frame = self.recv_frame()\n  File \"C:\\Users\\eldoj\\PycharmProjects\\MARK6_V2.0\\.venv\\lib\\site-packages\\websocket\\_core.py\", line 445, in recv_frame\n    return self.frame_buffer.recv_frame()\n  File \"C:\\Users\\eldoj\\PycharmProjects\\MARK6_V2.0\\.venv\\lib\\site-packages\\websocket\\_abnf.py\", line 338, in recv_frame\n    self.recv_header()\n  File \"C:\\Users\\eldoj\\PycharmProjects\\MARK6_V2.0\\.venv\\lib\\site-packages\\websocket\\_abnf.py\", line 294, in recv_header\n    header = self.recv_strict(2)\n  File \"C:\\Users\\eldoj\\PycharmProjects\\MARK6_V2.0\\.venv\\lib\\site-packages\\websocket\\_abnf.py\", line 373, in recv_strict\n    bytes_ = self.recv(min(16384, shortage))\n  File \"C:\\Users\\eldoj\\PycharmProjects\\MARK6_V2.0\\.venv\\lib\\site-packages\\websocket\\_core.py\", line 529, in _recv\n    return recv(self.sock, bufsize)\n  File \"C:\\Users\\eldoj\\PycharmProjects\\MARK6_V2.0\\.venv\\lib\\site-packages\\websocket\\_socket.py\", line 122, in recv\n    raise WebSocketConnectionClosedException(\nwebsocket._exceptions.WebSocketConnectionClosedException: Connection to remote host was lost.\n\nDuring handling of the above exception, another exception occurred:\n\nTraceback (most recent call last):\n  File \"C:\\Users\\eldoj\\PycharmProjects\\MARK6_V2.0\\.venv\\lib\\site-packages\\fyers_apiv3\\FyersWebsocket\\data_ws.py\", line 1333, in __symbol_conversion\n    if symbol_value[3] != \"\":\nTypeError: 'NoneType' object is not subscriptable","exception_name":"TypeError"}
{"level":"ERROR","location":"[<lambda>:1663] data_ws","message":"[Errno 11001] getaddrinfo failed","timestamp":"2025-06-11 14:18:27,184+0530","service":"FyersDataSocket"}
{"level":"ERROR","location":"[exception:108] fyers_logger","message":"HTTPSConnectionPool(host='api-t1.fyers.in', port=443): Max retries exceeded with url: /data/symbol-token (Caused by NameResolutionError(\"<urllib3.connection.HTTPSConnection object at 0x000002117FAFCA00>: Failed to resolve 'api-t1.fyers.in' ([Errno 11001] getaddrinfo failed)\"))","timestamp":"2025-06-11 14:18:29,202+0530","service":"FyersDataSocket","exception":"Traceback (most recent call last):\n  File \"C:\\Users\\eldoj\\PycharmProjects\\MARK6_V2.0\\.venv\\lib\\site-packages\\websocket\\_http.py\", line 155, in _get_addrinfo_list\n    addrinfo_list = socket.getaddrinfo(\n  File \"C:\\Users\\eldoj\\AppData\\Local\\Programs\\Python\\Python310\\lib\\socket.py\", line 955, in getaddrinfo\n    for res in _socket.getaddrinfo(host, port, family, type, proto, flags):\nsocket.gaierror: [Errno 11001] getaddrinfo failed\n\nDuring handling of the above exception, another exception occurred:\n\nTraceback (most recent call last):\n  File \"C:\\Users\\eldoj\\PycharmProjects\\MARK6_V2.0\\.venv\\lib\\site-packages\\websocket\\_app.py\", line 412, in setSock\n    self.sock.connect(\n  File \"C:\\Users\\eldoj\\PycharmProjects\\MARK6_V2.0\\.venv\\lib\\site-packages\\websocket\\_core.py\", line 249, in connect\n    self.sock, addrs = connect(url, self.sock_opt, proxy_info(**options),\n  File \"C:\\Users\\eldoj\\PycharmProjects\\MARK6_V2.0\\.venv\\lib\\site-packages\\websocket\\_http.py\", line 122, in connect\n    addrinfo_list, need_tunnel, auth = _get_addrinfo_list(\n  File \"C:\\Users\\eldoj\\PycharmProjects\\MARK6_V2.0\\.venv\\lib\\site-packages\\websocket\\_http.py\", line 167, in _get_addrinfo_list\n    raise WebSocketAddressException(e)\nwebsocket._exceptions.WebSocketAddressException: [Errno 11001] getaddrinfo failed\n\nDuring handling of the above exception, another exception occurred:\n\nTraceback (most recent call last):\n  File \"C:\\Users\\eldoj\\PycharmProjects\\MARK6_V2.0\\.venv\\lib\\site-packages\\urllib3\\connection.py\", line 198, in _new_conn\n    sock = connection.create_connection(\n  File \"C:\\Users\\eldoj\\PycharmProjects\\MARK6_V2.0\\.venv\\lib\\site-packages\\urllib3\\util\\connection.py\", line 60, in create_connection\n    for res in socket.getaddrinfo(host, port, family, socket.SOCK_STREAM):\n  File \"C:\\Users\\eldoj\\AppData\\Local\\Programs\\Python\\Python310\\lib\\socket.py\", line 955, in getaddrinfo\n    for res in _socket.getaddrinfo(host, port, family, type, proto, flags):\nsocket.gaierror: [Errno 11001] getaddrinfo failed\n\nThe above exception was the direct cause of the following exception:\n\nTraceback (most recent call last):\n  File \"C:\\Users\\eldoj\\PycharmProjects\\MARK6_V2.0\\.venv\\lib\\site-packages\\urllib3\\connectionpool.py\", line 787, in urlopen\n    response = self._make_request(\n  File \"C:\\Users\\eldoj\\PycharmProjects\\MARK6_V2.0\\.venv\\lib\\site-packages\\urllib3\\connectionpool.py\", line 488, in _make_request\n    raise new_e\n  File \"C:\\Users\\eldoj\\PycharmProjects\\MARK6_V2.0\\.venv\\lib\\site-packages\\urllib3\\connectionpool.py\", line 464, in _make_request\n    self._validate_conn(conn)\n  File \"C:\\Users\\eldoj\\PycharmProjects\\MARK6_V2.0\\.venv\\lib\\site-packages\\urllib3\\connectionpool.py\", line 1093, in _validate_conn\n    conn.connect()\n  File \"C:\\Users\\eldoj\\PycharmProjects\\MARK6_V2.0\\.venv\\lib\\site-packages\\urllib3\\connection.py\", line 704, in connect\n    self.sock = sock = self._new_conn()\n  File \"C:\\Users\\eldoj\\PycharmProjects\\MARK6_V2.0\\.venv\\lib\\site-packages\\urllib3\\connection.py\", line 205, in _new_conn\n    raise NameResolutionError(self.host, self, e) from e\nurllib3.exceptions.NameResolutionError: <urllib3.connection.HTTPSConnection object at 0x000002117FAFCA00>: Failed to resolve 'api-t1.fyers.in' ([Errno 11001] getaddrinfo failed)\n\nThe above exception was the direct cause of the following exception:\n\nTraceback (most recent call last):\n  File \"C:\\Users\\eldoj\\PycharmProjects\\MARK6_V2.0\\.venv\\lib\\site-packages\\requests\\adapters.py\", line 486, in send\n    resp = conn.urlopen(\n  File \"C:\\Users\\eldoj\\PycharmProjects\\MARK6_V2.0\\.venv\\lib\\site-packages\\urllib3\\connectionpool.py\", line 841, in urlopen\n    retries = retries.increment(\n  File \"C:\\Users\\eldoj\\PycharmProjects\\MARK6_V2.0\\.venv\\lib\\site-packages\\urllib3\\util\\retry.py\", line 519, in increment\n    raise MaxRetryError(_pool, url, reason) from reason  # type: ignore[arg-type]\nurllib3.exceptions.MaxRetryError: HTTPSConnectionPool(host='api-t1.fyers.in', port=443): Max retries exceeded with url: /data/symbol-token (Caused by NameResolutionError(\"<urllib3.connection.HTTPSConnection object at 0x000002117FAFCA00>: Failed to resolve 'api-t1.fyers.in' ([Errno 11001] getaddrinfo failed)\"))\n\nDuring handling of the above exception, another exception occurred:\n\nTraceback (most recent call last):\n  File \"C:\\Users\\eldoj\\PycharmProjects\\MARK6_V2.0\\.venv\\lib\\site-packages\\fyers_apiv3\\FyersWebsocket\\data_ws.py\", line 63, in symbol_to_hsmtoken\n    response = requests.post(\n  File \"C:\\Users\\eldoj\\PycharmProjects\\MARK6_V2.0\\.venv\\lib\\site-packages\\requests\\api.py\", line 115, in post\n    return request(\"post\", url, data=data, json=json, **kwargs)\n  File \"C:\\Users\\eldoj\\PycharmProjects\\MARK6_V2.0\\.venv\\lib\\site-packages\\requests\\api.py\", line 59, in request\n    return session.request(method=method, url=url, **kwargs)\n  File \"C:\\Users\\eldoj\\PycharmProjects\\MARK6_V2.0\\.venv\\lib\\site-packages\\requests\\sessions.py\", line 589, in request\n    resp = self.send(prep, **send_kwargs)\n  File \"C:\\Users\\eldoj\\PycharmProjects\\MARK6_V2.0\\.venv\\lib\\site-packages\\requests\\sessions.py\", line 703, in send\n    r = adapter.send(request, **kwargs)\n  File \"C:\\Users\\eldoj\\PycharmProjects\\MARK6_V2.0\\.venv\\lib\\site-packages\\requests\\adapters.py\", line 519, in send\n    raise ConnectionError(e, request=request)\nrequests.exceptions.ConnectionError: HTTPSConnectionPool(host='api-t1.fyers.in', port=443): Max retries exceeded with url: /data/symbol-token (Caused by NameResolutionError(\"<urllib3.connection.HTTPSConnection object at 0x000002117FAFCA00>: Failed to resolve 'api-t1.fyers.in' ([Errno 11001] getaddrinfo failed)\"))","exception_name":"ConnectionError"}
{"level":"ERROR","location":"[exception:108] fyers_logger","message":"'NoneType' object is not subscriptable","timestamp":"2025-06-11 14:18:29,209+0530","service":"FyersDataSocket","exception":"Traceback (most recent call last):\n  File \"C:\\Users\\eldoj\\PycharmProjects\\MARK6_V2.0\\.venv\\lib\\site-packages\\websocket\\_http.py\", line 155, in _get_addrinfo_list\n    addrinfo_list = socket.getaddrinfo(\n  File \"C:\\Users\\eldoj\\AppData\\Local\\Programs\\Python\\Python310\\lib\\socket.py\", line 955, in getaddrinfo\n    for res in _socket.getaddrinfo(host, port, family, type, proto, flags):\nsocket.gaierror: [Errno 11001] getaddrinfo failed\n\nDuring handling of the above exception, another exception occurred:\n\nTraceback (most recent call last):\n  File \"C:\\Users\\eldoj\\PycharmProjects\\MARK6_V2.0\\.venv\\lib\\site-packages\\websocket\\_app.py\", line 412, in setSock\n    self.sock.connect(\n  File \"C:\\Users\\eldoj\\PycharmProjects\\MARK6_V2.0\\.venv\\lib\\site-packages\\websocket\\_core.py\", line 249, in connect\n    self.sock, addrs = connect(url, self.sock_opt, proxy_info(**options),\n  File \"C:\\Users\\eldoj\\PycharmProjects\\MARK6_V2.0\\.venv\\lib\\site-packages\\websocket\\_http.py\", line 122, in connect\n    addrinfo_list, need_tunnel, auth = _get_addrinfo_list(\n  File \"C:\\Users\\eldoj\\PycharmProjects\\MARK6_V2.0\\.venv\\lib\\site-packages\\websocket\\_http.py\", line 167, in _get_addrinfo_list\n    raise WebSocketAddressException(e)\nwebsocket._exceptions.WebSocketAddressException: [Errno 11001] getaddrinfo failed\n\nDuring handling of the above exception, another exception occurred:\n\nTraceback (most recent call last):\n  File \"C:\\Users\\eldoj\\PycharmProjects\\MARK6_V2.0\\.venv\\lib\\site-packages\\fyers_apiv3\\FyersWebsocket\\data_ws.py\", line 1333, in __symbol_conversion\n    if symbol_value[3] != \"\":\nTypeError: 'NoneType' object is not subscriptable","exception_name":"TypeError"}
{"level":"ERROR","location":"[<lambda>:1663] data_ws","message":"[Errno 11001] getaddrinfo failed","timestamp":"2025-06-11 14:18:32,197+0530","service":"FyersDataSocket"}
{"level":"ERROR","location":"[exception:108] fyers_logger","message":"HTTPSConnectionPool(host='api-t1.fyers.in', port=443): Max retries exceeded with url: /data/symbol-token (Caused by NameResolutionError(\"<urllib3.connection.HTTPSConnection object at 0x000002117FAFDEA0>: Failed to resolve 'api-t1.fyers.in' ([Errno 11001] getaddrinfo failed)\"))","timestamp":"2025-06-11 14:18:34,213+0530","service":"FyersDataSocket","exception":"Traceback (most recent call last):\n  File \"C:\\Users\\eldoj\\PycharmProjects\\MARK6_V2.0\\.venv\\lib\\site-packages\\websocket\\_http.py\", line 155, in _get_addrinfo_list\n    addrinfo_list = socket.getaddrinfo(\n  File \"C:\\Users\\eldoj\\AppData\\Local\\Programs\\Python\\Python310\\lib\\socket.py\", line 955, in getaddrinfo\n    for res in _socket.getaddrinfo(host, port, family, type, proto, flags):\nsocket.gaierror: [Errno 11001] getaddrinfo failed\n\nDuring handling of the above exception, another exception occurred:\n\nTraceback (most recent call last):\n  File \"C:\\Users\\eldoj\\PycharmProjects\\MARK6_V2.0\\.venv\\lib\\site-packages\\websocket\\_app.py\", line 412, in setSock\n    self.sock.connect(\n  File \"C:\\Users\\eldoj\\PycharmProjects\\MARK6_V2.0\\.venv\\lib\\site-packages\\websocket\\_core.py\", line 249, in connect\n    self.sock, addrs = connect(url, self.sock_opt, proxy_info(**options),\n  File \"C:\\Users\\eldoj\\PycharmProjects\\MARK6_V2.0\\.venv\\lib\\site-packages\\websocket\\_http.py\", line 122, in connect\n    addrinfo_list, need_tunnel, auth = _get_addrinfo_list(\n  File \"C:\\Users\\eldoj\\PycharmProjects\\MARK6_V2.0\\.venv\\lib\\site-packages\\websocket\\_http.py\", line 167, in _get_addrinfo_list\n    raise WebSocketAddressException(e)\nwebsocket._exceptions.WebSocketAddressException: [Errno 11001] getaddrinfo failed\n\nDuring handling of the above exception, another exception occurred:\n\nTraceback (most recent call last):\n  File \"C:\\Users\\eldoj\\PycharmProjects\\MARK6_V2.0\\.venv\\lib\\site-packages\\urllib3\\connection.py\", line 198, in _new_conn\n    sock = connection.create_connection(\n  File \"C:\\Users\\eldoj\\PycharmProjects\\MARK6_V2.0\\.venv\\lib\\site-packages\\urllib3\\util\\connection.py\", line 60, in create_connection\n    for res in socket.getaddrinfo(host, port, family, socket.SOCK_STREAM):\n  File \"C:\\Users\\eldoj\\AppData\\Local\\Programs\\Python\\Python310\\lib\\socket.py\", line 955, in getaddrinfo\n    for res in _socket.getaddrinfo(host, port, family, type, proto, flags):\nsocket.gaierror: [Errno 11001] getaddrinfo failed\n\nThe above exception was the direct cause of the following exception:\n\nTraceback (most recent call last):\n  File \"C:\\Users\\eldoj\\PycharmProjects\\MARK6_V2.0\\.venv\\lib\\site-packages\\urllib3\\connectionpool.py\", line 787, in urlopen\n    response = self._make_request(\n  File \"C:\\Users\\eldoj\\PycharmProjects\\MARK6_V2.0\\.venv\\lib\\site-packages\\urllib3\\connectionpool.py\", line 488, in _make_request\n    raise new_e\n  File \"C:\\Users\\eldoj\\PycharmProjects\\MARK6_V2.0\\.venv\\lib\\site-packages\\urllib3\\connectionpool.py\", line 464, in _make_request\n    self._validate_conn(conn)\n  File \"C:\\Users\\eldoj\\PycharmProjects\\MARK6_V2.0\\.venv\\lib\\site-packages\\urllib3\\connectionpool.py\", line 1093, in _validate_conn\n    conn.connect()\n  File \"C:\\Users\\eldoj\\PycharmProjects\\MARK6_V2.0\\.venv\\lib\\site-packages\\urllib3\\connection.py\", line 704, in connect\n    self.sock = sock = self._new_conn()\n  File \"C:\\Users\\eldoj\\PycharmProjects\\MARK6_V2.0\\.venv\\lib\\site-packages\\urllib3\\connection.py\", line 205, in _new_conn\n    raise NameResolutionError(self.host, self, e) from e\nurllib3.exceptions.NameResolutionError: <urllib3.connection.HTTPSConnection object at 0x000002117FAFDEA0>: Failed to resolve 'api-t1.fyers.in' ([Errno 11001] getaddrinfo failed)\n\nThe above exception was the direct cause of the following exception:\n\nTraceback (most recent call last):\n  File \"C:\\Users\\eldoj\\PycharmProjects\\MARK6_V2.0\\.venv\\lib\\site-packages\\requests\\adapters.py\", line 486, in send\n    resp = conn.urlopen(\n  File \"C:\\Users\\eldoj\\PycharmProjects\\MARK6_V2.0\\.venv\\lib\\site-packages\\urllib3\\connectionpool.py\", line 841, in urlopen\n    retries = retries.increment(\n  File \"C:\\Users\\eldoj\\PycharmProjects\\MARK6_V2.0\\.venv\\lib\\site-packages\\urllib3\\util\\retry.py\", line 519, in increment\n    raise MaxRetryError(_pool, url, reason) from reason  # type: ignore[arg-type]\nurllib3.exceptions.MaxRetryError: HTTPSConnectionPool(host='api-t1.fyers.in', port=443): Max retries exceeded with url: /data/symbol-token (Caused by NameResolutionError(\"<urllib3.connection.HTTPSConnection object at 0x000002117FAFDEA0>: Failed to resolve 'api-t1.fyers.in' ([Errno 11001] getaddrinfo failed)\"))\n\nDuring handling of the above exception, another exception occurred:\n\nTraceback (most recent call last):\n  File \"C:\\Users\\eldoj\\PycharmProjects\\MARK6_V2.0\\.venv\\lib\\site-packages\\fyers_apiv3\\FyersWebsocket\\data_ws.py\", line 63, in symbol_to_hsmtoken\n    response = requests.post(\n  File \"C:\\Users\\eldoj\\PycharmProjects\\MARK6_V2.0\\.venv\\lib\\site-packages\\requests\\api.py\", line 115, in post\n    return request(\"post\", url, data=data, json=json, **kwargs)\n  File \"C:\\Users\\eldoj\\PycharmProjects\\MARK6_V2.0\\.venv\\lib\\site-packages\\requests\\api.py\", line 59, in request\n    return session.request(method=method, url=url, **kwargs)\n  File \"C:\\Users\\eldoj\\PycharmProjects\\MARK6_V2.0\\.venv\\lib\\site-packages\\requests\\sessions.py\", line 589, in request\n    resp = self.send(prep, **send_kwargs)\n  File \"C:\\Users\\eldoj\\PycharmProjects\\MARK6_V2.0\\.venv\\lib\\site-packages\\requests\\sessions.py\", line 703, in send\n    r = adapter.send(request, **kwargs)\n  File \"C:\\Users\\eldoj\\PycharmProjects\\MARK6_V2.0\\.venv\\lib\\site-packages\\requests\\adapters.py\", line 519, in send\n    raise ConnectionError(e, request=request)\nrequests.exceptions.ConnectionError: HTTPSConnectionPool(host='api-t1.fyers.in', port=443): Max retries exceeded with url: /data/symbol-token (Caused by NameResolutionError(\"<urllib3.connection.HTTPSConnection object at 0x000002117FAFDEA0>: Failed to resolve 'api-t1.fyers.in' ([Errno 11001] getaddrinfo failed)\"))","exception_name":"ConnectionError"}
{"level":"ERROR","location":"[exception:108] fyers_logger","message":"'NoneType' object is not subscriptable","timestamp":"2025-06-11 14:18:34,215+0530","service":"FyersDataSocket","exception":"Traceback (most recent call last):\n  File \"C:\\Users\\eldoj\\PycharmProjects\\MARK6_V2.0\\.venv\\lib\\site-packages\\websocket\\_http.py\", line 155, in _get_addrinfo_list\n    addrinfo_list = socket.getaddrinfo(\n  File \"C:\\Users\\eldoj\\AppData\\Local\\Programs\\Python\\Python310\\lib\\socket.py\", line 955, in getaddrinfo\n    for res in _socket.getaddrinfo(host, port, family, type, proto, flags):\nsocket.gaierror: [Errno 11001] getaddrinfo failed\n\nDuring handling of the above exception, another exception occurred:\n\nTraceback (most recent call last):\n  File \"C:\\Users\\eldoj\\PycharmProjects\\MARK6_V2.0\\.venv\\lib\\site-packages\\websocket\\_app.py\", line 412, in setSock\n    self.sock.connect(\n  File \"C:\\Users\\eldoj\\PycharmProjects\\MARK6_V2.0\\.venv\\lib\\site-packages\\websocket\\_core.py\", line 249, in connect\n    self.sock, addrs = connect(url, self.sock_opt, proxy_info(**options),\n  File \"C:\\Users\\eldoj\\PycharmProjects\\MARK6_V2.0\\.venv\\lib\\site-packages\\websocket\\_http.py\", line 122, in connect\n    addrinfo_list, need_tunnel, auth = _get_addrinfo_list(\n  File \"C:\\Users\\eldoj\\PycharmProjects\\MARK6_V2.0\\.venv\\lib\\site-packages\\websocket\\_http.py\", line 167, in _get_addrinfo_list\n    raise WebSocketAddressException(e)\nwebsocket._exceptions.WebSocketAddressException: [Errno 11001] getaddrinfo failed\n\nDuring handling of the above exception, another exception occurred:\n\nTraceback (most recent call last):\n  File \"C:\\Users\\eldoj\\PycharmProjects\\MARK6_V2.0\\.venv\\lib\\site-packages\\fyers_apiv3\\FyersWebsocket\\data_ws.py\", line 1333, in __symbol_conversion\n    if symbol_value[3] != \"\":\nTypeError: 'NoneType' object is not subscriptable","exception_name":"TypeError"}
{"level":"ERROR","location":"[exception:108] fyers_logger","message":"HTTPSConnectionPool(host='api-t1.fyers.in', port=443): Max retries exceeded with url: /data/symbol-token (Caused by NameResolutionError(\"<urllib3.connection.HTTPSConnection object at 0x000002117FD85330>: Failed to resolve 'api-t1.fyers.in' ([Errno 11001] getaddrinfo failed)\"))","timestamp":"2025-06-11 14:18:43,239+0530","service":"FyersDataSocket","exception":"Traceback (most recent call last):\n  File \"C:\\Users\\eldoj\\PycharmProjects\\MARK6_V2.0\\.venv\\lib\\site-packages\\websocket\\_http.py\", line 155, in _get_addrinfo_list\n    addrinfo_list = socket.getaddrinfo(\n  File \"C:\\Users\\eldoj\\AppData\\Local\\Programs\\Python\\Python310\\lib\\socket.py\", line 955, in getaddrinfo\n    for res in _socket.getaddrinfo(host, port, family, type, proto, flags):\nsocket.gaierror: [Errno 11001] getaddrinfo failed\n\nDuring handling of the above exception, another exception occurred:\n\nTraceback (most recent call last):\n  File \"C:\\Users\\eldoj\\PycharmProjects\\MARK6_V2.0\\.venv\\lib\\site-packages\\websocket\\_app.py\", line 412, in setSock\n    self.sock.connect(\n  File \"C:\\Users\\eldoj\\PycharmProjects\\MARK6_V2.0\\.venv\\lib\\site-packages\\websocket\\_core.py\", line 249, in connect\n    self.sock, addrs = connect(url, self.sock_opt, proxy_info(**options),\n  File \"C:\\Users\\eldoj\\PycharmProjects\\MARK6_V2.0\\.venv\\lib\\site-packages\\websocket\\_http.py\", line 122, in connect\n    addrinfo_list, need_tunnel, auth = _get_addrinfo_list(\n  File \"C:\\Users\\eldoj\\PycharmProjects\\MARK6_V2.0\\.venv\\lib\\site-packages\\websocket\\_http.py\", line 167, in _get_addrinfo_list\n    raise WebSocketAddressException(e)\nwebsocket._exceptions.WebSocketAddressException: [Errno 11001] getaddrinfo failed\n\nDuring handling of the above exception, another exception occurred:\n\nTraceback (most recent call last):\n  File \"C:\\Users\\eldoj\\PycharmProjects\\MARK6_V2.0\\.venv\\lib\\site-packages\\urllib3\\connection.py\", line 198, in _new_conn\n    sock = connection.create_connection(\n  File \"C:\\Users\\eldoj\\PycharmProjects\\MARK6_V2.0\\.venv\\lib\\site-packages\\urllib3\\util\\connection.py\", line 60, in create_connection\n    for res in socket.getaddrinfo(host, port, family, socket.SOCK_STREAM):\n  File \"C:\\Users\\eldoj\\AppData\\Local\\Programs\\Python\\Python310\\lib\\socket.py\", line 955, in getaddrinfo\n    for res in _socket.getaddrinfo(host, port, family, type, proto, flags):\nsocket.gaierror: [Errno 11001] getaddrinfo failed\n\nThe above exception was the direct cause of the following exception:\n\nTraceback (most recent call last):\n  File \"C:\\Users\\eldoj\\PycharmProjects\\MARK6_V2.0\\.venv\\lib\\site-packages\\urllib3\\connectionpool.py\", line 787, in urlopen\n    response = self._make_request(\n  File \"C:\\Users\\eldoj\\PycharmProjects\\MARK6_V2.0\\.venv\\lib\\site-packages\\urllib3\\connectionpool.py\", line 488, in _make_request\n    raise new_e\n  File \"C:\\Users\\eldoj\\PycharmProjects\\MARK6_V2.0\\.venv\\lib\\site-packages\\urllib3\\connectionpool.py\", line 464, in _make_request\n    self._validate_conn(conn)\n  File \"C:\\Users\\eldoj\\PycharmProjects\\MARK6_V2.0\\.venv\\lib\\site-packages\\urllib3\\connectionpool.py\", line 1093, in _validate_conn\n    conn.connect()\n  File \"C:\\Users\\eldoj\\PycharmProjects\\MARK6_V2.0\\.venv\\lib\\site-packages\\urllib3\\connection.py\", line 704, in connect\n    self.sock = sock = self._new_conn()\n  File \"C:\\Users\\eldoj\\PycharmProjects\\MARK6_V2.0\\.venv\\lib\\site-packages\\urllib3\\connection.py\", line 205, in _new_conn\n    raise NameResolutionError(self.host, self, e) from e\nurllib3.exceptions.NameResolutionError: <urllib3.connection.HTTPSConnection object at 0x000002117FD85330>: Failed to resolve 'api-t1.fyers.in' ([Errno 11001] getaddrinfo failed)\n\nThe above exception was the direct cause of the following exception:\n\nTraceback (most recent call last):\n  File \"C:\\Users\\eldoj\\PycharmProjects\\MARK6_V2.0\\.venv\\lib\\site-packages\\requests\\adapters.py\", line 486, in send\n    resp = conn.urlopen(\n  File \"C:\\Users\\eldoj\\PycharmProjects\\MARK6_V2.0\\.venv\\lib\\site-packages\\urllib3\\connectionpool.py\", line 841, in urlopen\n    retries = retries.increment(\n  File \"C:\\Users\\eldoj\\PycharmProjects\\MARK6_V2.0\\.venv\\lib\\site-packages\\urllib3\\util\\retry.py\", line 519, in increment\n    raise MaxRetryError(_pool, url, reason) from reason  # type: ignore[arg-type]\nurllib3.exceptions.MaxRetryError: HTTPSConnectionPool(host='api-t1.fyers.in', port=443): Max retries exceeded with url: /data/symbol-token (Caused by NameResolutionError(\"<urllib3.connection.HTTPSConnection object at 0x000002117FD85330>: Failed to resolve 'api-t1.fyers.in' ([Errno 11001] getaddrinfo failed)\"))\n\nDuring handling of the above exception, another exception occurred:\n\nTraceback (most recent call last):\n  File \"C:\\Users\\eldoj\\PycharmProjects\\MARK6_V2.0\\.venv\\lib\\site-packages\\fyers_apiv3\\FyersWebsocket\\data_ws.py\", line 63, in symbol_to_hsmtoken\n    response = requests.post(\n  File \"C:\\Users\\eldoj\\PycharmProjects\\MARK6_V2.0\\.venv\\lib\\site-packages\\requests\\api.py\", line 115, in post\n    return request(\"post\", url, data=data, json=json, **kwargs)\n  File \"C:\\Users\\eldoj\\PycharmProjects\\MARK6_V2.0\\.venv\\lib\\site-packages\\requests\\api.py\", line 59, in request\n    return session.request(method=method, url=url, **kwargs)\n  File \"C:\\Users\\eldoj\\PycharmProjects\\MARK6_V2.0\\.venv\\lib\\site-packages\\requests\\sessions.py\", line 589, in request\n    resp = self.send(prep, **send_kwargs)\n  File \"C:\\Users\\eldoj\\PycharmProjects\\MARK6_V2.0\\.venv\\lib\\site-packages\\requests\\sessions.py\", line 703, in send\n    r = adapter.send(request, **kwargs)\n  File \"C:\\Users\\eldoj\\PycharmProjects\\MARK6_V2.0\\.venv\\lib\\site-packages\\requests\\adapters.py\", line 519, in send\n    raise ConnectionError(e, request=request)\nrequests.exceptions.ConnectionError: HTTPSConnectionPool(host='api-t1.fyers.in', port=443): Max retries exceeded with url: /data/symbol-token (Caused by NameResolutionError(\"<urllib3.connection.HTTPSConnection object at 0x000002117FD85330>: Failed to resolve 'api-t1.fyers.in' ([Errno 11001] getaddrinfo failed)\"))","exception_name":"ConnectionError"}
{"level":"ERROR","location":"[exception:108] fyers_logger","message":"'NoneType' object is not subscriptable","timestamp":"2025-06-11 14:18:43,241+0530","service":"FyersDataSocket","exception":"Traceback (most recent call last):\n  File \"C:\\Users\\eldoj\\PycharmProjects\\MARK6_V2.0\\.venv\\lib\\site-packages\\websocket\\_http.py\", line 155, in _get_addrinfo_list\n    addrinfo_list = socket.getaddrinfo(\n  File \"C:\\Users\\eldoj\\AppData\\Local\\Programs\\Python\\Python310\\lib\\socket.py\", line 955, in getaddrinfo\n    for res in _socket.getaddrinfo(host, port, family, type, proto, flags):\nsocket.gaierror: [Errno 11001] getaddrinfo failed\n\nDuring handling of the above exception, another exception occurred:\n\nTraceback (most recent call last):\n  File \"C:\\Users\\eldoj\\PycharmProjects\\MARK6_V2.0\\.venv\\lib\\site-packages\\websocket\\_app.py\", line 412, in setSock\n    self.sock.connect(\n  File \"C:\\Users\\eldoj\\PycharmProjects\\MARK6_V2.0\\.venv\\lib\\site-packages\\websocket\\_core.py\", line 249, in connect\n    self.sock, addrs = connect(url, self.sock_opt, proxy_info(**options),\n  File \"C:\\Users\\eldoj\\PycharmProjects\\MARK6_V2.0\\.venv\\lib\\site-packages\\websocket\\_http.py\", line 122, in connect\n    addrinfo_list, need_tunnel, auth = _get_addrinfo_list(\n  File \"C:\\Users\\eldoj\\PycharmProjects\\MARK6_V2.0\\.venv\\lib\\site-packages\\websocket\\_http.py\", line 167, in _get_addrinfo_list\n    raise WebSocketAddressException(e)\nwebsocket._exceptions.WebSocketAddressException: [Errno 11001] getaddrinfo failed\n\nDuring handling of the above exception, another exception occurred:\n\nTraceback (most recent call last):\n  File \"C:\\Users\\eldoj\\PycharmProjects\\MARK6_V2.0\\.venv\\lib\\site-packages\\fyers_apiv3\\FyersWebsocket\\data_ws.py\", line 1333, in __symbol_conversion\n    if symbol_value[3] != \"\":\nTypeError: 'NoneType' object is not subscriptable","exception_name":"TypeError"}
{"level":"ERROR","location":"[<lambda>:1663] data_ws","message":"[Errno 11001] getaddrinfo failed","timestamp":"2025-06-11 14:18:49,244+0530","service":"FyersDataSocket"}
{"level":"ERROR","location":"[<lambda>:1663] data_ws","message":"[WinError 10053] An established connection was aborted by the software in your host machine","timestamp":"2025-06-11 14:19:07,773+0530","service":"FyersDataSocket"}
{"level":"ERROR","location":"[exception:108] fyers_logger","message":"HTTPSConnectionPool(host='api-t1.fyers.in', port=443): Max retries exceeded with url: /data/symbol-token (Caused by NewConnectionError('<urllib3.connection.HTTPSConnection object at 0x000002117FD84CA0>: Failed to establish a new connection: [WinError 10053] An established connection was aborted by the software in your host machine'))","timestamp":"2025-06-11 14:19:07,774+0530","service":"FyersDataSocket","exception":"Traceback (most recent call last):\n  File \"C:\\Users\\eldoj\\PycharmProjects\\MARK6_V2.0\\.venv\\lib\\site-packages\\websocket\\_http.py\", line 155, in _get_addrinfo_list\n    addrinfo_list = socket.getaddrinfo(\n  File \"C:\\Users\\eldoj\\AppData\\Local\\Programs\\Python\\Python310\\lib\\socket.py\", line 955, in getaddrinfo\n    for res in _socket.getaddrinfo(host, port, family, type, proto, flags):\nsocket.gaierror: [Errno 11001] getaddrinfo failed\n\nDuring handling of the above exception, another exception occurred:\n\nTraceback (most recent call last):\n  File \"C:\\Users\\eldoj\\PycharmProjects\\MARK6_V2.0\\.venv\\lib\\site-packages\\websocket\\_app.py\", line 412, in setSock\n    self.sock.connect(\n  File \"C:\\Users\\eldoj\\PycharmProjects\\MARK6_V2.0\\.venv\\lib\\site-packages\\websocket\\_core.py\", line 249, in connect\n    self.sock, addrs = connect(url, self.sock_opt, proxy_info(**options),\n  File \"C:\\Users\\eldoj\\PycharmProjects\\MARK6_V2.0\\.venv\\lib\\site-packages\\websocket\\_http.py\", line 122, in connect\n    addrinfo_list, need_tunnel, auth = _get_addrinfo_list(\n  File \"C:\\Users\\eldoj\\PycharmProjects\\MARK6_V2.0\\.venv\\lib\\site-packages\\websocket\\_http.py\", line 167, in _get_addrinfo_list\n    raise WebSocketAddressException(e)\nwebsocket._exceptions.WebSocketAddressException: [Errno 11001] getaddrinfo failed\n\nDuring handling of the above exception, another exception occurred:\n\nTraceback (most recent call last):\n  File \"C:\\Users\\eldoj\\PycharmProjects\\MARK6_V2.0\\.venv\\lib\\site-packages\\urllib3\\connection.py\", line 198, in _new_conn\n    sock = connection.create_connection(\n  File \"C:\\Users\\eldoj\\PycharmProjects\\MARK6_V2.0\\.venv\\lib\\site-packages\\urllib3\\util\\connection.py\", line 85, in create_connection\n    raise err\n  File \"C:\\Users\\eldoj\\PycharmProjects\\MARK6_V2.0\\.venv\\lib\\site-packages\\urllib3\\util\\connection.py\", line 73, in create_connection\n    sock.connect(sa)\nConnectionAbortedError: [WinError 10053] An established connection was aborted by the software in your host machine\n\nThe above exception was the direct cause of the following exception:\n\nTraceback (most recent call last):\n  File \"C:\\Users\\eldoj\\PycharmProjects\\MARK6_V2.0\\.venv\\lib\\site-packages\\urllib3\\connectionpool.py\", line 787, in urlopen\n    response = self._make_request(\n  File \"C:\\Users\\eldoj\\PycharmProjects\\MARK6_V2.0\\.venv\\lib\\site-packages\\urllib3\\connectionpool.py\", line 488, in _make_request\n    raise new_e\n  File \"C:\\Users\\eldoj\\PycharmProjects\\MARK6_V2.0\\.venv\\lib\\site-packages\\urllib3\\connectionpool.py\", line 464, in _make_request\n    self._validate_conn(conn)\n  File \"C:\\Users\\eldoj\\PycharmProjects\\MARK6_V2.0\\.venv\\lib\\site-packages\\urllib3\\connectionpool.py\", line 1093, in _validate_conn\n    conn.connect()\n  File \"C:\\Users\\eldoj\\PycharmProjects\\MARK6_V2.0\\.venv\\lib\\site-packages\\urllib3\\connection.py\", line 704, in connect\n    self.sock = sock = self._new_conn()\n  File \"C:\\Users\\eldoj\\PycharmProjects\\MARK6_V2.0\\.venv\\lib\\site-packages\\urllib3\\connection.py\", line 213, in _new_conn\n    raise NewConnectionError(\nurllib3.exceptions.NewConnectionError: <urllib3.connection.HTTPSConnection object at 0x000002117FD84CA0>: Failed to establish a new connection: [WinError 10053] An established connection was aborted by the software in your host machine\n\nThe above exception was the direct cause of the following exception:\n\nTraceback (most recent call last):\n  File \"C:\\Users\\eldoj\\PycharmProjects\\MARK6_V2.0\\.venv\\lib\\site-packages\\requests\\adapters.py\", line 486, in send\n    resp = conn.urlopen(\n  File \"C:\\Users\\eldoj\\PycharmProjects\\MARK6_V2.0\\.venv\\lib\\site-packages\\urllib3\\connectionpool.py\", line 841, in urlopen\n    retries = retries.increment(\n  File \"C:\\Users\\eldoj\\PycharmProjects\\MARK6_V2.0\\.venv\\lib\\site-packages\\urllib3\\util\\retry.py\", line 519, in increment\n    raise MaxRetryError(_pool, url, reason) from reason  # type: ignore[arg-type]\nurllib3.exceptions.MaxRetryError: HTTPSConnectionPool(host='api-t1.fyers.in', port=443): Max retries exceeded with url: /data/symbol-token (Caused by NewConnectionError('<urllib3.connection.HTTPSConnection object at 0x000002117FD84CA0>: Failed to establish a new connection: [WinError 10053] An established connection was aborted by the software in your host machine'))\n\nDuring handling of the above exception, another exception occurred:\n\nTraceback (most recent call last):\n  File \"C:\\Users\\eldoj\\PycharmProjects\\MARK6_V2.0\\.venv\\lib\\site-packages\\fyers_apiv3\\FyersWebsocket\\data_ws.py\", line 63, in symbol_to_hsmtoken\n    response = requests.post(\n  File \"C:\\Users\\eldoj\\PycharmProjects\\MARK6_V2.0\\.venv\\lib\\site-packages\\requests\\api.py\", line 115, in post\n    return request(\"post\", url, data=data, json=json, **kwargs)\n  File \"C:\\Users\\eldoj\\PycharmProjects\\MARK6_V2.0\\.venv\\lib\\site-packages\\requests\\api.py\", line 59, in request\n    return session.request(method=method, url=url, **kwargs)\n  File \"C:\\Users\\eldoj\\PycharmProjects\\MARK6_V2.0\\.venv\\lib\\site-packages\\requests\\sessions.py\", line 589, in request\n    resp = self.send(prep, **send_kwargs)\n  File \"C:\\Users\\eldoj\\PycharmProjects\\MARK6_V2.0\\.venv\\lib\\site-packages\\requests\\sessions.py\", line 703, in send\n    r = adapter.send(request, **kwargs)\n  File \"C:\\Users\\eldoj\\PycharmProjects\\MARK6_V2.0\\.venv\\lib\\site-packages\\requests\\adapters.py\", line 519, in send\n    raise ConnectionError(e, request=request)\nrequests.exceptions.ConnectionError: HTTPSConnectionPool(host='api-t1.fyers.in', port=443): Max retries exceeded with url: /data/symbol-token (Caused by NewConnectionError('<urllib3.connection.HTTPSConnection object at 0x000002117FD84CA0>: Failed to establish a new connection: [WinError 10053] An established connection was aborted by the software in your host machine'))","exception_name":"ConnectionError"}
{"level":"ERROR","location":"[exception:108] fyers_logger","message":"'NoneType' object is not subscriptable","timestamp":"2025-06-11 14:19:07,777+0530","service":"FyersDataSocket","exception":"Traceback (most recent call last):\n  File \"C:\\Users\\eldoj\\PycharmProjects\\MARK6_V2.0\\.venv\\lib\\site-packages\\websocket\\_http.py\", line 155, in _get_addrinfo_list\n    addrinfo_list = socket.getaddrinfo(\n  File \"C:\\Users\\eldoj\\AppData\\Local\\Programs\\Python\\Python310\\lib\\socket.py\", line 955, in getaddrinfo\n    for res in _socket.getaddrinfo(host, port, family, type, proto, flags):\nsocket.gaierror: [Errno 11001] getaddrinfo failed\n\nDuring handling of the above exception, another exception occurred:\n\nTraceback (most recent call last):\n  File \"C:\\Users\\eldoj\\PycharmProjects\\MARK6_V2.0\\.venv\\lib\\site-packages\\websocket\\_app.py\", line 412, in setSock\n    self.sock.connect(\n  File \"C:\\Users\\eldoj\\PycharmProjects\\MARK6_V2.0\\.venv\\lib\\site-packages\\websocket\\_core.py\", line 249, in connect\n    self.sock, addrs = connect(url, self.sock_opt, proxy_info(**options),\n  File \"C:\\Users\\eldoj\\PycharmProjects\\MARK6_V2.0\\.venv\\lib\\site-packages\\websocket\\_http.py\", line 122, in connect\n    addrinfo_list, need_tunnel, auth = _get_addrinfo_list(\n  File \"C:\\Users\\eldoj\\PycharmProjects\\MARK6_V2.0\\.venv\\lib\\site-packages\\websocket\\_http.py\", line 167, in _get_addrinfo_list\n    raise WebSocketAddressException(e)\nwebsocket._exceptions.WebSocketAddressException: [Errno 11001] getaddrinfo failed\n\nDuring handling of the above exception, another exception occurred:\n\nTraceback (most recent call last):\n  File \"C:\\Users\\eldoj\\PycharmProjects\\MARK6_V2.0\\.venv\\lib\\site-packages\\fyers_apiv3\\FyersWebsocket\\data_ws.py\", line 1333, in __symbol_conversion\n    if symbol_value[3] != \"\":\nTypeError: 'NoneType' object is not subscriptable","exception_name":"TypeError"}
{"level":"ERROR","location":"[<lambda>:1663] data_ws","message":"[WinError 10060] A connection attempt failed because the connected party did not properly respond after a period of time, or established connection failed because connected host has failed to respond","timestamp":"2025-06-11 14:19:38,815+0530","service":"FyersDataSocket"}
{"level":"ERROR","location":"[exception:108] fyers_logger","message":"HTTPSConnectionPool(host='api-t1.fyers.in', port=443): Max retries exceeded with url: /data/symbol-token (Caused by ConnectTimeoutError(<urllib3.connection.HTTPSConnection object at 0x000002117FAFC1F0>, 'Connection to api-t1.fyers.in timed out. (connect timeout=None)'))","timestamp":"2025-06-11 14:19:40,818+0530","service":"FyersDataSocket","exception":"Traceback (most recent call last):\n  File \"C:\\Users\\eldoj\\PycharmProjects\\MARK6_V2.0\\.venv\\lib\\site-packages\\websocket\\_app.py\", line 412, in setSock\n    self.sock.connect(\n  File \"C:\\Users\\eldoj\\PycharmProjects\\MARK6_V2.0\\.venv\\lib\\site-packages\\websocket\\_core.py\", line 249, in connect\n    self.sock, addrs = connect(url, self.sock_opt, proxy_info(**options),\n  File \"C:\\Users\\eldoj\\PycharmProjects\\MARK6_V2.0\\.venv\\lib\\site-packages\\websocket\\_http.py\", line 130, in connect\n    sock = _open_socket(addrinfo_list, options.sockopt, options.timeout)\n  File \"C:\\Users\\eldoj\\PycharmProjects\\MARK6_V2.0\\.venv\\lib\\site-packages\\websocket\\_http.py\", line 197, in _open_socket\n    raise error\n  File \"C:\\Users\\eldoj\\PycharmProjects\\MARK6_V2.0\\.venv\\lib\\site-packages\\websocket\\_http.py\", line 185, in _open_socket\n    sock.connect(address)\nConnectionAbortedError: [WinError 10053] An established connection was aborted by the software in your host machine\n\nDuring handling of the above exception, another exception occurred:\n\nTraceback (most recent call last):\n  File \"C:\\Users\\eldoj\\PycharmProjects\\MARK6_V2.0\\.venv\\lib\\site-packages\\urllib3\\connection.py\", line 198, in _new_conn\n    sock = connection.create_connection(\n  File \"C:\\Users\\eldoj\\PycharmProjects\\MARK6_V2.0\\.venv\\lib\\site-packages\\urllib3\\util\\connection.py\", line 85, in create_connection\n    raise err\n  File \"C:\\Users\\eldoj\\PycharmProjects\\MARK6_V2.0\\.venv\\lib\\site-packages\\urllib3\\util\\connection.py\", line 73, in create_connection\n    sock.connect(sa)\nTimeoutError: [WinError 10060] A connection attempt failed because the connected party did not properly respond after a period of time, or established connection failed because connected host has failed to respond\n\nThe above exception was the direct cause of the following exception:\n\nTraceback (most recent call last):\n  File \"C:\\Users\\eldoj\\PycharmProjects\\MARK6_V2.0\\.venv\\lib\\site-packages\\urllib3\\connectionpool.py\", line 787, in urlopen\n    response = self._make_request(\n  File \"C:\\Users\\eldoj\\PycharmProjects\\MARK6_V2.0\\.venv\\lib\\site-packages\\urllib3\\connectionpool.py\", line 488, in _make_request\n    raise new_e\n  File \"C:\\Users\\eldoj\\PycharmProjects\\MARK6_V2.0\\.venv\\lib\\site-packages\\urllib3\\connectionpool.py\", line 464, in _make_request\n    self._validate_conn(conn)\n  File \"C:\\Users\\eldoj\\PycharmProjects\\MARK6_V2.0\\.venv\\lib\\site-packages\\urllib3\\connectionpool.py\", line 1093, in _validate_conn\n    conn.connect()\n  File \"C:\\Users\\eldoj\\PycharmProjects\\MARK6_V2.0\\.venv\\lib\\site-packages\\urllib3\\connection.py\", line 704, in connect\n    self.sock = sock = self._new_conn()\n  File \"C:\\Users\\eldoj\\PycharmProjects\\MARK6_V2.0\\.venv\\lib\\site-packages\\urllib3\\connection.py\", line 207, in _new_conn\n    raise ConnectTimeoutError(\nurllib3.exceptions.ConnectTimeoutError: (<urllib3.connection.HTTPSConnection object at 0x000002117FAFC1F0>, 'Connection to api-t1.fyers.in timed out. (connect timeout=None)')\n\nThe above exception was the direct cause of the following exception:\n\nTraceback (most recent call last):\n  File \"C:\\Users\\eldoj\\PycharmProjects\\MARK6_V2.0\\.venv\\lib\\site-packages\\requests\\adapters.py\", line 486, in send\n    resp = conn.urlopen(\n  File \"C:\\Users\\eldoj\\PycharmProjects\\MARK6_V2.0\\.venv\\lib\\site-packages\\urllib3\\connectionpool.py\", line 841, in urlopen\n    retries = retries.increment(\n  File \"C:\\Users\\eldoj\\PycharmProjects\\MARK6_V2.0\\.venv\\lib\\site-packages\\urllib3\\util\\retry.py\", line 519, in increment\n    raise MaxRetryError(_pool, url, reason) from reason  # type: ignore[arg-type]\nurllib3.exceptions.MaxRetryError: HTTPSConnectionPool(host='api-t1.fyers.in', port=443): Max retries exceeded with url: /data/symbol-token (Caused by ConnectTimeoutError(<urllib3.connection.HTTPSConnection object at 0x000002117FAFC1F0>, 'Connection to api-t1.fyers.in timed out. (connect timeout=None)'))\n\nDuring handling of the above exception, another exception occurred:\n\nTraceback (most recent call last):\n  File \"C:\\Users\\eldoj\\PycharmProjects\\MARK6_V2.0\\.venv\\lib\\site-packages\\fyers_apiv3\\FyersWebsocket\\data_ws.py\", line 63, in symbol_to_hsmtoken\n    response = requests.post(\n  File \"C:\\Users\\eldoj\\PycharmProjects\\MARK6_V2.0\\.venv\\lib\\site-packages\\requests\\api.py\", line 115, in post\n    return request(\"post\", url, data=data, json=json, **kwargs)\n  File \"C:\\Users\\eldoj\\PycharmProjects\\MARK6_V2.0\\.venv\\lib\\site-packages\\requests\\api.py\", line 59, in request\n    return session.request(method=method, url=url, **kwargs)\n  File \"C:\\Users\\eldoj\\PycharmProjects\\MARK6_V2.0\\.venv\\lib\\site-packages\\requests\\sessions.py\", line 589, in request\n    resp = self.send(prep, **send_kwargs)\n  File \"C:\\Users\\eldoj\\PycharmProjects\\MARK6_V2.0\\.venv\\lib\\site-packages\\requests\\sessions.py\", line 703, in send\n    r = adapter.send(request, **kwargs)\n  File \"C:\\Users\\eldoj\\PycharmProjects\\MARK6_V2.0\\.venv\\lib\\site-packages\\requests\\adapters.py\", line 507, in send\n    raise ConnectTimeout(e, request=request)\nrequests.exceptions.ConnectTimeout: HTTPSConnectionPool(host='api-t1.fyers.in', port=443): Max retries exceeded with url: /data/symbol-token (Caused by ConnectTimeoutError(<urllib3.connection.HTTPSConnection object at 0x000002117FAFC1F0>, 'Connection to api-t1.fyers.in timed out. (connect timeout=None)'))","exception_name":"ConnectTimeout"}
{"level":"ERROR","location":"[exception:108] fyers_logger","message":"'NoneType' object is not subscriptable","timestamp":"2025-06-11 14:19:40,821+0530","service":"FyersDataSocket","exception":"Traceback (most recent call last):\n  File \"C:\\Users\\eldoj\\PycharmProjects\\MARK6_V2.0\\.venv\\lib\\site-packages\\websocket\\_app.py\", line 412, in setSock\n    self.sock.connect(\n  File \"C:\\Users\\eldoj\\PycharmProjects\\MARK6_V2.0\\.venv\\lib\\site-packages\\websocket\\_core.py\", line 249, in connect\n    self.sock, addrs = connect(url, self.sock_opt, proxy_info(**options),\n  File \"C:\\Users\\eldoj\\PycharmProjects\\MARK6_V2.0\\.venv\\lib\\site-packages\\websocket\\_http.py\", line 130, in connect\n    sock = _open_socket(addrinfo_list, options.sockopt, options.timeout)\n  File \"C:\\Users\\eldoj\\PycharmProjects\\MARK6_V2.0\\.venv\\lib\\site-packages\\websocket\\_http.py\", line 197, in _open_socket\n    raise error\n  File \"C:\\Users\\eldoj\\PycharmProjects\\MARK6_V2.0\\.venv\\lib\\site-packages\\websocket\\_http.py\", line 185, in _open_socket\n    sock.connect(address)\nConnectionAbortedError: [WinError 10053] An established connection was aborted by the software in your host machine\n\nDuring handling of the above exception, another exception occurred:\n\nTraceback (most recent call last):\n  File \"C:\\Users\\eldoj\\PycharmProjects\\MARK6_V2.0\\.venv\\lib\\site-packages\\fyers_apiv3\\FyersWebsocket\\data_ws.py\", line 1333, in __symbol_conversion\n    if symbol_value[3] != \"\":\nTypeError: 'NoneType' object is not subscriptable","exception_name":"TypeError"}
{"level":"ERROR","location":"[<lambda>:1663] data_ws","message":"[WinError 10060] A connection attempt failed because the connected party did not properly respond after a period of time, or established connection failed because connected host has failed to respond","timestamp":"2025-06-11 14:20:10,026+0530","service":"FyersDataSocket"}
{"level":"ERROR","location":"[exception:108] fyers_logger","message":"HTTPSConnectionPool(host='api-t1.fyers.in', port=443): Max retries exceeded with url: /data/symbol-token (Caused by ConnectTimeoutError(<urllib3.connection.HTTPSConnection object at 0x000002117FD84220>, 'Connection to api-t1.fyers.in timed out. (connect timeout=None)'))","timestamp":"2025-06-11 14:20:12,135+0530","service":"FyersDataSocket","exception":"Traceback (most recent call last):\n  File \"C:\\Users\\eldoj\\PycharmProjects\\MARK6_V2.0\\.venv\\lib\\site-packages\\websocket\\_app.py\", line 412, in setSock\n    self.sock.connect(\n  File \"C:\\Users\\eldoj\\PycharmProjects\\MARK6_V2.0\\.venv\\lib\\site-packages\\websocket\\_core.py\", line 249, in connect\n    self.sock, addrs = connect(url, self.sock_opt, proxy_info(**options),\n  File \"C:\\Users\\eldoj\\PycharmProjects\\MARK6_V2.0\\.venv\\lib\\site-packages\\websocket\\_http.py\", line 130, in connect\n    sock = _open_socket(addrinfo_list, options.sockopt, options.timeout)\n  File \"C:\\Users\\eldoj\\PycharmProjects\\MARK6_V2.0\\.venv\\lib\\site-packages\\websocket\\_http.py\", line 197, in _open_socket\n    raise error\n  File \"C:\\Users\\eldoj\\PycharmProjects\\MARK6_V2.0\\.venv\\lib\\site-packages\\websocket\\_http.py\", line 185, in _open_socket\n    sock.connect(address)\nTimeoutError: [WinError 10060] A connection attempt failed because the connected party did not properly respond after a period of time, or established connection failed because connected host has failed to respond\n\nDuring handling of the above exception, another exception occurred:\n\nTraceback (most recent call last):\n  File \"C:\\Users\\eldoj\\PycharmProjects\\MARK6_V2.0\\.venv\\lib\\site-packages\\urllib3\\connection.py\", line 198, in _new_conn\n    sock = connection.create_connection(\n  File \"C:\\Users\\eldoj\\PycharmProjects\\MARK6_V2.0\\.venv\\lib\\site-packages\\urllib3\\util\\connection.py\", line 85, in create_connection\n    raise err\n  File \"C:\\Users\\eldoj\\PycharmProjects\\MARK6_V2.0\\.venv\\lib\\site-packages\\urllib3\\util\\connection.py\", line 73, in create_connection\n    sock.connect(sa)\nTimeoutError: [WinError 10060] A connection attempt failed because the connected party did not properly respond after a period of time, or established connection failed because connected host has failed to respond\n\nThe above exception was the direct cause of the following exception:\n\nTraceback (most recent call last):\n  File \"C:\\Users\\eldoj\\PycharmProjects\\MARK6_V2.0\\.venv\\lib\\site-packages\\urllib3\\connectionpool.py\", line 787, in urlopen\n    response = self._make_request(\n  File \"C:\\Users\\eldoj\\PycharmProjects\\MARK6_V2.0\\.venv\\lib\\site-packages\\urllib3\\connectionpool.py\", line 488, in _make_request\n    raise new_e\n  File \"C:\\Users\\eldoj\\PycharmProjects\\MARK6_V2.0\\.venv\\lib\\site-packages\\urllib3\\connectionpool.py\", line 464, in _make_request\n    self._validate_conn(conn)\n  File \"C:\\Users\\eldoj\\PycharmProjects\\MARK6_V2.0\\.venv\\lib\\site-packages\\urllib3\\connectionpool.py\", line 1093, in _validate_conn\n    conn.connect()\n  File \"C:\\Users\\eldoj\\PycharmProjects\\MARK6_V2.0\\.venv\\lib\\site-packages\\urllib3\\connection.py\", line 704, in connect\n    self.sock = sock = self._new_conn()\n  File \"C:\\Users\\eldoj\\PycharmProjects\\MARK6_V2.0\\.venv\\lib\\site-packages\\urllib3\\connection.py\", line 207, in _new_conn\n    raise ConnectTimeoutError(\nurllib3.exceptions.ConnectTimeoutError: (<urllib3.connection.HTTPSConnection object at 0x000002117FD84220>, 'Connection to api-t1.fyers.in timed out. (connect timeout=None)')\n\nThe above exception was the direct cause of the following exception:\n\nTraceback (most recent call last):\n  File \"C:\\Users\\eldoj\\PycharmProjects\\MARK6_V2.0\\.venv\\lib\\site-packages\\requests\\adapters.py\", line 486, in send\n    resp = conn.urlopen(\n  File \"C:\\Users\\eldoj\\PycharmProjects\\MARK6_V2.0\\.venv\\lib\\site-packages\\urllib3\\connectionpool.py\", line 841, in urlopen\n    retries = retries.increment(\n  File \"C:\\Users\\eldoj\\PycharmProjects\\MARK6_V2.0\\.venv\\lib\\site-packages\\urllib3\\util\\retry.py\", line 519, in increment\n    raise MaxRetryError(_pool, url, reason) from reason  # type: ignore[arg-type]\nurllib3.exceptions.MaxRetryError: HTTPSConnectionPool(host='api-t1.fyers.in', port=443): Max retries exceeded with url: /data/symbol-token (Caused by ConnectTimeoutError(<urllib3.connection.HTTPSConnection object at 0x000002117FD84220>, 'Connection to api-t1.fyers.in timed out. (connect timeout=None)'))\n\nDuring handling of the above exception, another exception occurred:\n\nTraceback (most recent call last):\n  File \"C:\\Users\\eldoj\\PycharmProjects\\MARK6_V2.0\\.venv\\lib\\site-packages\\fyers_apiv3\\FyersWebsocket\\data_ws.py\", line 63, in symbol_to_hsmtoken\n    response = requests.post(\n  File \"C:\\Users\\eldoj\\PycharmProjects\\MARK6_V2.0\\.venv\\lib\\site-packages\\requests\\api.py\", line 115, in post\n    return request(\"post\", url, data=data, json=json, **kwargs)\n  File \"C:\\Users\\eldoj\\PycharmProjects\\MARK6_V2.0\\.venv\\lib\\site-packages\\requests\\api.py\", line 59, in request\n    return session.request(method=method, url=url, **kwargs)\n  File \"C:\\Users\\eldoj\\PycharmProjects\\MARK6_V2.0\\.venv\\lib\\site-packages\\requests\\sessions.py\", line 589, in request\n    resp = self.send(prep, **send_kwargs)\n  File \"C:\\Users\\eldoj\\PycharmProjects\\MARK6_V2.0\\.venv\\lib\\site-packages\\requests\\sessions.py\", line 703, in send\n    r = adapter.send(request, **kwargs)\n  File \"C:\\Users\\eldoj\\PycharmProjects\\MARK6_V2.0\\.venv\\lib\\site-packages\\requests\\adapters.py\", line 507, in send\n    raise ConnectTimeout(e, request=request)\nrequests.exceptions.ConnectTimeout: HTTPSConnectionPool(host='api-t1.fyers.in', port=443): Max retries exceeded with url: /data/symbol-token (Caused by ConnectTimeoutError(<urllib3.connection.HTTPSConnection object at 0x000002117FD84220>, 'Connection to api-t1.fyers.in timed out. (connect timeout=None)'))","exception_name":"ConnectTimeout"}
{"level":"ERROR","location":"[exception:108] fyers_logger","message":"'NoneType' object is not subscriptable","timestamp":"2025-06-11 14:20:12,138+0530","service":"FyersDataSocket","exception":"Traceback (most recent call last):\n  File \"C:\\Users\\eldoj\\PycharmProjects\\MARK6_V2.0\\.venv\\lib\\site-packages\\websocket\\_app.py\", line 412, in setSock\n    self.sock.connect(\n  File \"C:\\Users\\eldoj\\PycharmProjects\\MARK6_V2.0\\.venv\\lib\\site-packages\\websocket\\_core.py\", line 249, in connect\n    self.sock, addrs = connect(url, self.sock_opt, proxy_info(**options),\n  File \"C:\\Users\\eldoj\\PycharmProjects\\MARK6_V2.0\\.venv\\lib\\site-packages\\websocket\\_http.py\", line 130, in connect\n    sock = _open_socket(addrinfo_list, options.sockopt, options.timeout)\n  File \"C:\\Users\\eldoj\\PycharmProjects\\MARK6_V2.0\\.venv\\lib\\site-packages\\websocket\\_http.py\", line 197, in _open_socket\n    raise error\n  File \"C:\\Users\\eldoj\\PycharmProjects\\MARK6_V2.0\\.venv\\lib\\site-packages\\websocket\\_http.py\", line 185, in _open_socket\n    sock.connect(address)\nTimeoutError: [WinError 10060] A connection attempt failed because the connected party did not properly respond after a period of time, or established connection failed because connected host has failed to respond\n\nDuring handling of the above exception, another exception occurred:\n\nTraceback (most recent call last):\n  File \"C:\\Users\\eldoj\\PycharmProjects\\MARK6_V2.0\\.venv\\lib\\site-packages\\fyers_apiv3\\FyersWebsocket\\data_ws.py\", line 1333, in __symbol_conversion\n    if symbol_value[3] != \"\":\nTypeError: 'NoneType' object is not subscriptable","exception_name":"TypeError"}
{"level":"ERROR","location":"[<lambda>:1663] data_ws","message":"Connection to remote host was lost.","timestamp":"2025-06-12 13:54:59,097+0530","service":"FyersDataSocket"}
{"level":"ERROR","location":"[<lambda>:1663] data_ws","message":"Connection to remote host was lost.","timestamp":"2025-06-12 15:44:25,229+0530","service":"FyersDataSocket"}
{"level":"ERROR","location":"[<lambda>:1663] data_ws","message":"Connection to remote host was lost.","timestamp":"2025-06-12 15:53:08,752+0530","service":"FyersDataSocket"}
{"level":"ERROR","location":"[<lambda>:1663] data_ws","message":"Connection to remote host was lost.","timestamp":"2025-06-16 09:15:43,853+0530","service":"FyersDataSocket"}
{"level":"ERROR","location":"[<lambda>:1663] data_ws","message":"Connection to remote host was lost.","timestamp":"2025-06-16 11:14:35,693+0530","service":"FyersDataSocket"}
{"level":"ERROR","location":"[<lambda>:1663] data_ws","message":"Connection to remote host was lost.","timestamp":"2025-06-16 14:25:35,387+0530","service":"FyersDataSocket"}
{"level":"ERROR","location":"[<lambda>:1663] data_ws","message":"Connection to remote host was lost.","timestamp":"2025-06-16 15:25:19,248+0530","service":"FyersDataSocket"}
{"level":"ERROR","location":"[<lambda>:1663] data_ws","message":"[Errno 2] No such file or directory","timestamp":"2025-06-16 15:25:40,446+0530","service":"FyersDataSocket"}
{"level":"ERROR","location":"[<lambda>:1663] data_ws","message":"Connection to remote host was lost.","timestamp":"2025-06-16 15:27:11,229+0530","service":"FyersDataSocket"}
{"level":"ERROR","location":"[<lambda>:1663] data_ws","message":"Connection to remote host was lost.","timestamp":"2025-06-17 09:39:17,518+0530","service":"FyersDataSocket"}
{"level":"ERROR","location":"[<lambda>:1663] data_ws","message":"Connection to remote host was lost.","timestamp":"2025-06-17 19:51:50,901+0530","service":"FyersDataSocket"}
{"level":"ERROR","location":"[<lambda>:1663] data_ws","message":"Connection to remote host was lost.","timestamp":"2025-06-17 21:25:33,409+0530","service":"FyersDataSocket"}
{"level":"ERROR","location":"[<lambda>:1663] data_ws","message":"Connection to remote host was lost.","timestamp":"2025-06-17 21:56:04,141+0530","service":"FyersDataSocket"}
{"level":"ERROR","location":"[<lambda>:1663] data_ws","message":"Connection to remote host was lost.","timestamp":"2025-06-17 22:08:55,874+0530","service":"FyersDataSocket"}
{"level":"ERROR","location":"[<lambda>:1663] data_ws","message":"Connection to remote host was lost.","timestamp":"2025-06-17 23:14:30,128+0530","service":"FyersDataSocket"}
{"level":"ERROR","location":"[<lambda>:1663] data_ws","message":"Connection to remote host was lost.","timestamp":"2025-06-18 01:16:34,535+0530","service":"FyersDataSocket"}
{"level":"ERROR","location":"[<lambda>:1663] data_ws","message":"Connection to remote host was lost.","timestamp":"2025-06-18 05:16:32,725+0530","service":"FyersDataSocket"}
{"level":"ERROR","location":"[<lambda>:1663] data_ws","message":"Connection to remote host was lost.","timestamp":"2025-06-18 06:21:42,864+0530","service":"FyersDataSocket"}
{"level":"ERROR","location":"[access_token_to_hsmtoken:272] data_ws","message":{"type":"cn","code":-99,"message":"Token is expired","s":"error"},"timestamp":"2025-06-18 06:21:47,878+0530","service":"FyersDataSocket"}
{"level":"ERROR","location":"[__symbol_conversion:1334] data_ws","message":{"code":-300,"message":"Please provide valid token","s":"error","type":"sub"},"timestamp":"2025-06-18 06:21:50,032+0530","service":"FyersDataSocket"}
{"level":"ERROR","location":"[<lambda>:1663] data_ws","message":"Connection to remote host was lost.","timestamp":"2025-06-18 20:47:24,794+0530","service":"FyersDataSocket"}
{"level":"ERROR","location":"[<lambda>:1663] data_ws","message":"Connection to remote host was lost.","timestamp":"2025-06-18 21:12:26,625+0530","service":"FyersDataSocket"}
{"level":"ERROR","location":"[<lambda>:1663] data_ws","message":"[Errno 11004] getaddrinfo failed","timestamp":"2025-06-18 21:18:20,789+0530","service":"FyersDataSocket"}
{"level":"ERROR","location":"[exception:108] fyers_logger","message":"'StockBot' object has no attribute 'loop'","timestamp":"2025-06-19 09:48:45,788+0530","service":"FyersDataSocket","exception":"Traceback (most recent call last):\n  File \"C:\\Users\\eldoj\\PycharmProjects\\MARK6_V2.0\\.venv\\lib\\site-packages\\fyers_apiv3\\FyersWebsocket\\data_ws.py\", line 1433, in On_message\n    self.OnMessage(message)\n  File \"C:\\Users\\eldoj\\PycharmProjects\\MARK6_V2.0\\.venv\\Scripts\\myScripts\\MasterBot.py\", line 71, in onmessage\n    self.bots[symbol].handle_message(message)\n  File \"C:\\Users\\eldoj\\PycharmProjects\\MARK6_V2.0\\.venv\\Scripts\\myScripts\\StockBot.py\", line 115, in handle_message\n    self.loop\nAttributeError: 'StockBot' object has no attribute 'loop'","exception_name":"AttributeError"}
{"level":"ERROR","location":"[On_message:1447] data_ws","message":"'StockBot' object has no attribute 'loop'","timestamp":"2025-06-19 09:48:45,794+0530","service":"FyersDataSocket"}
{"level":"ERROR","location":"[exception:108] fyers_logger","message":"'StockBot' object has no attribute 'loop'","timestamp":"2025-06-19 09:48:45,794+0530","service":"FyersDataSocket","exception":"Traceback (most recent call last):\n  File \"C:\\Users\\eldoj\\PycharmProjects\\MARK6_V2.0\\.venv\\lib\\site-packages\\fyers_apiv3\\FyersWebsocket\\data_ws.py\", line 1433, in On_message\n    self.OnMessage(message)\n  File \"C:\\Users\\eldoj\\PycharmProjects\\MARK6_V2.0\\.venv\\Scripts\\myScripts\\MasterBot.py\", line 71, in onmessage\n    self.bots[symbol].handle_message(message)\n  File \"C:\\Users\\eldoj\\PycharmProjects\\MARK6_V2.0\\.venv\\Scripts\\myScripts\\StockBot.py\", line 115, in handle_message\n    self.loop\nAttributeError: 'StockBot' object has no attribute 'loop'","exception_name":"AttributeError"}
{"level":"ERROR","location":"[On_message:1447] data_ws","message":"'StockBot' object has no attribute 'loop'","timestamp":"2025-06-19 09:48:45,794+0530","service":"FyersDataSocket"}
{"level":"ERROR","location":"[exception:108] fyers_logger","message":"'StockBot' object has no attribute 'loop'","timestamp":"2025-06-19 09:48:45,795+0530","service":"FyersDataSocket","exception":"Traceback (most recent call last):\n  File \"C:\\Users\\eldoj\\PycharmProjects\\MARK6_V2.0\\.venv\\lib\\site-packages\\fyers_apiv3\\FyersWebsocket\\data_ws.py\", line 1433, in On_message\n    self.OnMessage(message)\n  File \"C:\\Users\\eldoj\\PycharmProjects\\MARK6_V2.0\\.venv\\Scripts\\myScripts\\MasterBot.py\", line 71, in onmessage\n    self.bots[symbol].handle_message(message)\n  File \"C:\\Users\\eldoj\\PycharmProjects\\MARK6_V2.0\\.venv\\Scripts\\myScripts\\StockBot.py\", line 115, in handle_message\n    self.loop\nAttributeError: 'StockBot' object has no attribute 'loop'","exception_name":"AttributeError"}
{"level":"ERROR","location":"[On_message:1447] data_ws","message":"'StockBot' object has no attribute 'loop'","timestamp":"2025-06-19 09:48:45,795+0530","service":"FyersDataSocket"}
{"level":"ERROR","location":"[exception:108] fyers_logger","message":"'StockBot' object has no attribute 'loop'","timestamp":"2025-06-19 09:48:46,407+0530","service":"FyersDataSocket","exception":"Traceback (most recent call last):\n  File \"C:\\Users\\eldoj\\PycharmProjects\\MARK6_V2.0\\.venv\\lib\\site-packages\\fyers_apiv3\\FyersWebsocket\\data_ws.py\", line 1433, in On_message\n    self.OnMessage(message)\n  File \"C:\\Users\\eldoj\\PycharmProjects\\MARK6_V2.0\\.venv\\Scripts\\myScripts\\MasterBot.py\", line 71, in onmessage\n    self.bots[symbol].handle_message(message)\n  File \"C:\\Users\\eldoj\\PycharmProjects\\MARK6_V2.0\\.venv\\Scripts\\myScripts\\StockBot.py\", line 115, in handle_message\n    self.loop\nAttributeError: 'StockBot' object has no attribute 'loop'","exception_name":"AttributeError"}
{"level":"ERROR","location":"[On_message:1447] data_ws","message":"'StockBot' object has no attribute 'loop'","timestamp":"2025-06-19 09:48:46,408+0530","service":"FyersDataSocket"}
{"level":"ERROR","location":"[exception:108] fyers_logger","message":"'StockBot' object has no attribute 'loop'","timestamp":"2025-06-19 09:48:47,197+0530","service":"FyersDataSocket","exception":"Traceback (most recent call last):\n  File \"C:\\Users\\eldoj\\PycharmProjects\\MARK6_V2.0\\.venv\\lib\\site-packages\\fyers_apiv3\\FyersWebsocket\\data_ws.py\", line 1433, in On_message\n    self.OnMessage(message)\n  File \"C:\\Users\\eldoj\\PycharmProjects\\MARK6_V2.0\\.venv\\Scripts\\myScripts\\MasterBot.py\", line 71, in onmessage\n    self.bots[symbol].handle_message(message)\n  File \"C:\\Users\\eldoj\\PycharmProjects\\MARK6_V2.0\\.venv\\Scripts\\myScripts\\StockBot.py\", line 115, in handle_message\n    self.loop\nAttributeError: 'StockBot' object has no attribute 'loop'","exception_name":"AttributeError"}
{"level":"ERROR","location":"[On_message:1447] data_ws","message":"'StockBot' object has no attribute 'loop'","timestamp":"2025-06-19 09:48:47,197+0530","service":"FyersDataSocket"}
{"level":"ERROR","location":"[exception:108] fyers_logger","message":"'StockBot' object has no attribute 'loop'","timestamp":"2025-06-19 09:48:47,611+0530","service":"FyersDataSocket","exception":"Traceback (most recent call last):\n  File \"C:\\Users\\eldoj\\PycharmProjects\\MARK6_V2.0\\.venv\\lib\\site-packages\\fyers_apiv3\\FyersWebsocket\\data_ws.py\", line 1433, in On_message\n    self.OnMessage(message)\n  File \"C:\\Users\\eldoj\\PycharmProjects\\MARK6_V2.0\\.venv\\Scripts\\myScripts\\MasterBot.py\", line 71, in onmessage\n    self.bots[symbol].handle_message(message)\n  File \"C:\\Users\\eldoj\\PycharmProjects\\MARK6_V2.0\\.venv\\Scripts\\myScripts\\StockBot.py\", line 115, in handle_message\n    self.loop\nAttributeError: 'StockBot' object has no attribute 'loop'","exception_name":"AttributeError"}
{"level":"ERROR","location":"[On_message:1447] data_ws","message":"'StockBot' object has no attribute 'loop'","timestamp":"2025-06-19 09:48:47,611+0530","service":"FyersDataSocket"}
{"level":"ERROR","location":"[exception:108] fyers_logger","message":"'StockBot' object has no attribute 'loop'","timestamp":"2025-06-19 09:48:47,611+0530","service":"FyersDataSocket","exception":"Traceback (most recent call last):\n  File \"C:\\Users\\eldoj\\PycharmProjects\\MARK6_V2.0\\.venv\\lib\\site-packages\\fyers_apiv3\\FyersWebsocket\\data_ws.py\", line 1433, in On_message\n    self.OnMessage(message)\n  File \"C:\\Users\\eldoj\\PycharmProjects\\MARK6_V2.0\\.venv\\Scripts\\myScripts\\MasterBot.py\", line 71, in onmessage\n    self.bots[symbol].handle_message(message)\n  File \"C:\\Users\\eldoj\\PycharmProjects\\MARK6_V2.0\\.venv\\Scripts\\myScripts\\StockBot.py\", line 115, in handle_message\n    self.loop\nAttributeError: 'StockBot' object has no attribute 'loop'","exception_name":"AttributeError"}
{"level":"ERROR","location":"[On_message:1447] data_ws","message":"'StockBot' object has no attribute 'loop'","timestamp":"2025-06-19 09:48:47,613+0530","service":"FyersDataSocket"}
{"level":"ERROR","location":"[exception:108] fyers_logger","message":"Event loop is closed","timestamp":"2025-06-19 09:48:57,216+0530","service":"FyersDataSocket","exception":"Traceback (most recent call last):\n  File \"C:\\Users\\eldoj\\PycharmProjects\\MARK6_V2.0\\.venv\\lib\\site-packages\\fyers_apiv3\\FyersWebsocket\\data_ws.py\", line 1433, in On_message\n    self.OnMessage(message)\n  File \"C:\\Users\\eldoj\\PycharmProjects\\MARK6_V2.0\\.venv\\Scripts\\myScripts\\MasterBot.py\", line 71, in onmessage\n    self.bots[symbol].handle_message(message)\n  File \"C:\\Users\\eldoj\\PycharmProjects\\MARK6_V2.0\\.venv\\Scripts\\myScripts\\StockBot.py\", line 113, in handle_message\n    asyncio.run_coroutine_threadsafe(\n  File \"C:\\Users\\eldoj\\AppData\\Local\\Programs\\Python\\Python310\\lib\\asyncio\\tasks.py\", line 885, in run_coroutine_threadsafe\n    loop.call_soon_threadsafe(callback)\n  File \"C:\\Users\\eldoj\\AppData\\Local\\Programs\\Python\\Python310\\lib\\asyncio\\base_events.py\", line 795, in call_soon_threadsafe\n    self._check_closed()\n  File \"C:\\Users\\eldoj\\AppData\\Local\\Programs\\Python\\Python310\\lib\\asyncio\\base_events.py\", line 515, in _check_closed\n    raise RuntimeError('Event loop is closed')\nRuntimeError: Event loop is closed","exception_name":"RuntimeError"}
{"level":"ERROR","location":"[On_message:1447] data_ws","message":"Event loop is closed","timestamp":"2025-06-19 09:48:57,224+0530","service":"FyersDataSocket"}
{"level":"ERROR","location":"[exception:108] fyers_logger","message":"'StockBot' object has no attribute 'loop'","timestamp":"2025-06-19 09:51:14,697+0530","service":"FyersDataSocket","exception":"Traceback (most recent call last):\n  File \"C:\\Users\\eldoj\\PycharmProjects\\MARK6_V2.0\\.venv\\lib\\site-packages\\fyers_apiv3\\FyersWebsocket\\data_ws.py\", line 1433, in On_message\n    self.OnMessage(message)\n  File \"C:\\Users\\eldoj\\PycharmProjects\\MARK6_V2.0\\.venv\\Scripts\\myScripts\\MasterBot.py\", line 71, in onmessage\n    self.bots[symbol].handle_message(message)\n  File \"C:\\Users\\eldoj\\PycharmProjects\\MARK6_V2.0\\.venv\\Scripts\\myScripts\\StockBot.py\", line 115, in handle_message\n    self.loop\nAttributeError: 'StockBot' object has no attribute 'loop'","exception_name":"AttributeError"}
{"level":"ERROR","location":"[On_message:1447] data_ws","message":"'StockBot' object has no attribute 'loop'","timestamp":"2025-06-19 09:51:14,698+0530","service":"FyersDataSocket"}
{"level":"ERROR","location":"[exception:108] fyers_logger","message":"'StockBot' object has no attribute 'loop'","timestamp":"2025-06-19 09:51:14,698+0530","service":"FyersDataSocket","exception":"Traceback (most recent call last):\n  File \"C:\\Users\\eldoj\\PycharmProjects\\MARK6_V2.0\\.venv\\lib\\site-packages\\fyers_apiv3\\FyersWebsocket\\data_ws.py\", line 1433, in On_message\n    self.OnMessage(message)\n  File \"C:\\Users\\eldoj\\PycharmProjects\\MARK6_V2.0\\.venv\\Scripts\\myScripts\\MasterBot.py\", line 71, in onmessage\n    self.bots[symbol].handle_message(message)\n  File \"C:\\Users\\eldoj\\PycharmProjects\\MARK6_V2.0\\.venv\\Scripts\\myScripts\\StockBot.py\", line 115, in handle_message\n    self.loop\nAttributeError: 'StockBot' object has no attribute 'loop'","exception_name":"AttributeError"}
{"level":"ERROR","location":"[On_message:1447] data_ws","message":"'StockBot' object has no attribute 'loop'","timestamp":"2025-06-19 09:51:14,699+0530","service":"FyersDataSocket"}
{"level":"ERROR","location":"[exception:108] fyers_logger","message":"'StockBot' object has no attribute 'loop'","timestamp":"2025-06-19 09:51:14,699+0530","service":"FyersDataSocket","exception":"Traceback (most recent call last):\n  File \"C:\\Users\\eldoj\\PycharmProjects\\MARK6_V2.0\\.venv\\lib\\site-packages\\fyers_apiv3\\FyersWebsocket\\data_ws.py\", line 1433, in On_message\n    self.OnMessage(message)\n  File \"C:\\Users\\eldoj\\PycharmProjects\\MARK6_V2.0\\.venv\\Scripts\\myScripts\\MasterBot.py\", line 71, in onmessage\n    self.bots[symbol].handle_message(message)\n  File \"C:\\Users\\eldoj\\PycharmProjects\\MARK6_V2.0\\.venv\\Scripts\\myScripts\\StockBot.py\", line 115, in handle_message\n    self.loop\nAttributeError: 'StockBot' object has no attribute 'loop'","exception_name":"AttributeError"}
{"level":"ERROR","location":"[On_message:1447] data_ws","message":"'StockBot' object has no attribute 'loop'","timestamp":"2025-06-19 09:51:14,699+0530","service":"FyersDataSocket"}
{"level":"ERROR","location":"[exception:108] fyers_logger","message":"'StockBot' object has no attribute 'loop'","timestamp":"2025-06-19 09:51:14,818+0530","service":"FyersDataSocket","exception":"Traceback (most recent call last):\n  File \"C:\\Users\\eldoj\\PycharmProjects\\MARK6_V2.0\\.venv\\lib\\site-packages\\fyers_apiv3\\FyersWebsocket\\data_ws.py\", line 1433, in On_message\n    self.OnMessage(message)\n  File \"C:\\Users\\eldoj\\PycharmProjects\\MARK6_V2.0\\.venv\\Scripts\\myScripts\\MasterBot.py\", line 71, in onmessage\n    self.bots[symbol].handle_message(message)\n  File \"C:\\Users\\eldoj\\PycharmProjects\\MARK6_V2.0\\.venv\\Scripts\\myScripts\\StockBot.py\", line 115, in handle_message\n    self.loop\nAttributeError: 'StockBot' object has no attribute 'loop'","exception_name":"AttributeError"}
{"level":"ERROR","location":"[On_message:1447] data_ws","message":"'StockBot' object has no attribute 'loop'","timestamp":"2025-06-19 09:51:14,820+0530","service":"FyersDataSocket"}
{"level":"ERROR","location":"[exception:108] fyers_logger","message":"'StockBot' object has no attribute 'loop'","timestamp":"2025-06-19 09:51:15,209+0530","service":"FyersDataSocket","exception":"Traceback (most recent call last):\n  File \"C:\\Users\\eldoj\\PycharmProjects\\MARK6_V2.0\\.venv\\lib\\site-packages\\fyers_apiv3\\FyersWebsocket\\data_ws.py\", line 1433, in On_message\n    self.OnMessage(message)\n  File \"C:\\Users\\eldoj\\PycharmProjects\\MARK6_V2.0\\.venv\\Scripts\\myScripts\\MasterBot.py\", line 71, in onmessage\n    self.bots[symbol].handle_message(message)\n  File \"C:\\Users\\eldoj\\PycharmProjects\\MARK6_V2.0\\.venv\\Scripts\\myScripts\\StockBot.py\", line 115, in handle_message\n    self.loop\nAttributeError: 'StockBot' object has no attribute 'loop'","exception_name":"AttributeError"}
{"level":"ERROR","location":"[On_message:1447] data_ws","message":"'StockBot' object has no attribute 'loop'","timestamp":"2025-06-19 09:51:15,210+0530","service":"FyersDataSocket"}
{"level":"ERROR","location":"[exception:108] fyers_logger","message":"'StockBot' object has no attribute 'loop'","timestamp":"2025-06-19 09:51:15,620+0530","service":"FyersDataSocket","exception":"Traceback (most recent call last):\n  File \"C:\\Users\\eldoj\\PycharmProjects\\MARK6_V2.0\\.venv\\lib\\site-packages\\fyers_apiv3\\FyersWebsocket\\data_ws.py\", line 1433, in On_message\n    self.OnMessage(message)\n  File \"C:\\Users\\eldoj\\PycharmProjects\\MARK6_V2.0\\.venv\\Scripts\\myScripts\\MasterBot.py\", line 71, in onmessage\n    self.bots[symbol].handle_message(message)\n  File \"C:\\Users\\eldoj\\PycharmProjects\\MARK6_V2.0\\.venv\\Scripts\\myScripts\\StockBot.py\", line 115, in handle_message\n    self.loop\nAttributeError: 'StockBot' object has no attribute 'loop'","exception_name":"AttributeError"}
{"level":"ERROR","location":"[On_message:1447] data_ws","message":"'StockBot' object has no attribute 'loop'","timestamp":"2025-06-19 09:51:15,620+0530","service":"FyersDataSocket"}
{"level":"ERROR","location":"[exception:108] fyers_logger","message":"'StockBot' object has no attribute 'loop'","timestamp":"2025-06-19 09:51:16,019+0530","service":"FyersDataSocket","exception":"Traceback (most recent call last):\n  File \"C:\\Users\\eldoj\\PycharmProjects\\MARK6_V2.0\\.venv\\lib\\site-packages\\fyers_apiv3\\FyersWebsocket\\data_ws.py\", line 1433, in On_message\n    self.OnMessage(message)\n  File \"C:\\Users\\eldoj\\PycharmProjects\\MARK6_V2.0\\.venv\\Scripts\\myScripts\\MasterBot.py\", line 71, in onmessage\n    self.bots[symbol].handle_message(message)\n  File \"C:\\Users\\eldoj\\PycharmProjects\\MARK6_V2.0\\.venv\\Scripts\\myScripts\\StockBot.py\", line 115, in handle_message\n    self.loop\nAttributeError: 'StockBot' object has no attribute 'loop'","exception_name":"AttributeError"}
{"level":"ERROR","location":"[On_message:1447] data_ws","message":"'StockBot' object has no attribute 'loop'","timestamp":"2025-06-19 09:51:16,019+0530","service":"FyersDataSocket"}
{"level":"ERROR","location":"[exception:108] fyers_logger","message":"'StockBot' object has no attribute 'loop'","timestamp":"2025-06-19 09:51:16,020+0530","service":"FyersDataSocket","exception":"Traceback (most recent call last):\n  File \"C:\\Users\\eldoj\\PycharmProjects\\MARK6_V2.0\\.venv\\lib\\site-packages\\fyers_apiv3\\FyersWebsocket\\data_ws.py\", line 1433, in On_message\n    self.OnMessage(message)\n  File \"C:\\Users\\eldoj\\PycharmProjects\\MARK6_V2.0\\.venv\\Scripts\\myScripts\\MasterBot.py\", line 71, in onmessage\n    self.bots[symbol].handle_message(message)\n  File \"C:\\Users\\eldoj\\PycharmProjects\\MARK6_V2.0\\.venv\\Scripts\\myScripts\\StockBot.py\", line 115, in handle_message\n    self.loop\nAttributeError: 'StockBot' object has no attribute 'loop'","exception_name":"AttributeError"}
{"level":"ERROR","location":"[On_message:1447] data_ws","message":"'StockBot' object has no attribute 'loop'","timestamp":"2025-06-19 09:51:16,020+0530","service":"FyersDataSocket"}
{"level":"ERROR","location":"[<lambda>:1663] data_ws","message":"Connection to remote host was lost.","timestamp":"2025-06-19 14:08:47,668+0530","service":"FyersDataSocket"}
{"level":"ERROR","location":"[<lambda>:1663] data_ws","message":"EOF occurred in violation of protocol (_ssl.c:2396)","timestamp":"2025-06-19 16:37:36,477+0530","service":"FyersDataSocket"}
{"level":"ERROR","location":"[<lambda>:1663] data_ws","message":"Connection to remote host was lost.","timestamp":"2025-06-20 10:13:26,948+0530","service":"FyersDataSocket"}
{"level":"ERROR","location":"[<lambda>:1663] data_ws","message":"Connection to remote host was lost.","timestamp":"2025-06-20 11:26:11,504+0530","service":"FyersDataSocket"}
{"level":"ERROR","location":"[<lambda>:1663] data_ws","message":"Connection to remote host was lost.","timestamp":"2025-06-20 12:33:17,107+0530","service":"FyersDataSocket"}
{"level":"ERROR","location":"[<lambda>:1663] data_ws","message":"Connection to remote host was lost.","timestamp":"2025-06-20 12:35:31,981+0530","service":"FyersDataSocket"}
{"level":"ERROR","location":"[<lambda>:1663] data_ws","message":"Connection to remote host was lost.","timestamp":"2025-06-20 12:36:16,882+0530","service":"FyersDataSocket"}
{"level":"ERROR","location":"[<lambda>:1663] data_ws","message":"Connection to remote host was lost.","timestamp":"2025-06-20 12:38:00,742+0530","service":"FyersDataSocket"}
{"level":"ERROR","location":"[<lambda>:1663] data_ws","message":"Connection to remote host was lost.","timestamp":"2025-06-20 12:41:39,734+0530","service":"FyersDataSocket"}
{"level":"ERROR","location":"[<lambda>:1663] data_ws","message":"Connection to remote host was lost.","timestamp":"2025-06-20 12:41:45,099+0530","service":"FyersDataSocket"}
{"level":"ERROR","location":"[<lambda>:1663] data_ws","message":"Connection to remote host was lost.","timestamp":"2025-06-20 12:42:04,842+0530","service":"FyersDataSocket"}
{"level":"ERROR","location":"[<lambda>:1663] data_ws","message":"Connection to remote host was lost.","timestamp":"2025-06-23 09:28:41,871+0530","service":"FyersDataSocket"}
{"level":"ERROR","location":"[<lambda>:1663] data_ws","message":"Connection to remote host was lost.","timestamp":"2025-06-23 09:29:14,117+0530","service":"FyersDataSocket"}
{"level":"ERROR","location":"[exception:108] fyers_logger","message":"Event loop is closed","timestamp":"2025-06-23 10:59:42,197+0530","service":"FyersDataSocket","exception":"Traceback (most recent call last):\n  File \"C:\\Users\\eldoj\\PycharmProjects\\MARK6_V2.0\\.venv\\lib\\site-packages\\fyers_apiv3\\FyersWebsocket\\data_ws.py\", line 1433, in On_message\n    self.OnMessage(message)\n  File \"C:\\Users\\eldoj\\PycharmProjects\\MARK6_V2.0\\.venv\\Scripts\\myScripts\\MasterBot.py\", line 71, in onmessage\n    self.bots[symbol].handle_message(message)\n  File \"C:\\Users\\eldoj\\PycharmProjects\\MARK6_V2.0\\.venv\\Scripts\\myScripts\\StockBot.py\", line 113, in handle_message\n    f = asyncio.run_coroutine_threadsafe(\n  File \"C:\\Users\\eldoj\\AppData\\Local\\Programs\\Python\\Python310\\lib\\asyncio\\tasks.py\", line 885, in run_coroutine_threadsafe\n    loop.call_soon_threadsafe(callback)\n  File \"C:\\Users\\eldoj\\AppData\\Local\\Programs\\Python\\Python310\\lib\\asyncio\\base_events.py\", line 795, in call_soon_threadsafe\n    self._check_closed()\n  File \"C:\\Users\\eldoj\\AppData\\Local\\Programs\\Python\\Python310\\lib\\asyncio\\base_events.py\", line 515, in _check_closed\n    raise RuntimeError('Event loop is closed')\nRuntimeError: Event loop is closed","exception_name":"RuntimeError"}
{"level":"ERROR","location":"[On_message:1447] data_ws","message":"Event loop is closed","timestamp":"2025-06-23 10:59:42,216+0530","service":"FyersDataSocket"}
{"level":"ERROR","location":"[exception:108] fyers_logger","message":"Event loop is closed","timestamp":"2025-06-23 10:59:42,225+0530","service":"FyersDataSocket","exception":"Traceback (most recent call last):\n  File \"C:\\Users\\eldoj\\PycharmProjects\\MARK6_V2.0\\.venv\\lib\\site-packages\\fyers_apiv3\\FyersWebsocket\\data_ws.py\", line 1433, in On_message\n    self.OnMessage(message)\n  File \"C:\\Users\\eldoj\\PycharmProjects\\MARK6_V2.0\\.venv\\Scripts\\myScripts\\MasterBot.py\", line 71, in onmessage\n    self.bots[symbol].handle_message(message)\n  File \"C:\\Users\\eldoj\\PycharmProjects\\MARK6_V2.0\\.venv\\Scripts\\myScripts\\StockBot.py\", line 113, in handle_message\n    f = asyncio.run_coroutine_threadsafe(\n  File \"C:\\Users\\eldoj\\AppData\\Local\\Programs\\Python\\Python310\\lib\\asyncio\\tasks.py\", line 885, in run_coroutine_threadsafe\n    loop.call_soon_threadsafe(callback)\n  File \"C:\\Users\\eldoj\\AppData\\Local\\Programs\\Python\\Python310\\lib\\asyncio\\base_events.py\", line 795, in call_soon_threadsafe\n    self._check_closed()\n  File \"C:\\Users\\eldoj\\AppData\\Local\\Programs\\Python\\Python310\\lib\\asyncio\\base_events.py\", line 515, in _check_closed\n    raise RuntimeError('Event loop is closed')\nRuntimeError: Event loop is closed","exception_name":"RuntimeError"}
{"level":"ERROR","location":"[On_message:1447] data_ws","message":"Event loop is closed","timestamp":"2025-06-23 10:59:42,226+0530","service":"FyersDataSocket"}
{"level":"ERROR","location":"[<lambda>:1663] data_ws","message":"Connection to remote host was lost.","timestamp":"2025-06-24 09:56:58,433+0530","service":"FyersDataSocket"}
{"level":"ERROR","location":"[<lambda>:1663] data_ws","message":"Connection to remote host was lost.","timestamp":"2025-06-24 10:05:32,774+0530","service":"FyersDataSocket"}
{"level":"ERROR","location":"[<lambda>:1663] data_ws","message":"Connection to remote host was lost.","timestamp":"2025-06-27 09:04:00,289+0530","service":"FyersDataSocket"}
{"level":"ERROR","location":"[<lambda>:1663] data_ws","message":"Connection to remote host was lost.","timestamp":"2025-06-27 12:41:04,447+0530","service":"FyersDataSocket"}
{"level":"ERROR","location":"[<lambda>:1663] data_ws","message":"Connection to remote host was lost.","timestamp":"2025-06-27 12:43:51,316+0530","service":"FyersDataSocket"}
{"level":"ERROR","location":"[<lambda>:1663] data_ws","message":"Connection to remote host was lost.","timestamp":"2025-06-27 12:52:26,172+0530","service":"FyersDataSocket"}
{"level":"ERROR","location":"[exception:108] fyers_logger","message":"('Connection aborted.', ConnectionResetError(10054, 'An existing connection was forcibly closed by the remote host', None, 10054, None))","timestamp":"2025-06-27 12:53:10,491+0530","service":"FyersDataSocket","exception":"Traceback (most recent call last):\n  File \"C:\\Users\\eldoj\\PycharmProjects\\MARK6_V2.0\\.venv\\lib\\site-packages\\websocket\\_app.py\", line 428, in setSock\n    dispatcher.read(self.sock.sock, read, check)\n  File \"C:\\Users\\eldoj\\PycharmProjects\\MARK6_V2.0\\.venv\\lib\\site-packages\\websocket\\_app.py\", line 99, in read\n    if not read_callback():\n  File \"C:\\Users\\eldoj\\PycharmProjects\\MARK6_V2.0\\.venv\\lib\\site-packages\\websocket\\_app.py\", line 442, in read\n    raise e\n  File \"C:\\Users\\eldoj\\PycharmProjects\\MARK6_V2.0\\.venv\\lib\\site-packages\\websocket\\_app.py\", line 437, in read\n    op_code, frame = self.sock.recv_data_frame(True)\n  File \"C:\\Users\\eldoj\\PycharmProjects\\MARK6_V2.0\\.venv\\lib\\site-packages\\websocket\\_core.py\", line 406, in recv_data_frame\n    frame = self.recv_frame()\n  File \"C:\\Users\\eldoj\\PycharmProjects\\MARK6_V2.0\\.venv\\lib\\site-packages\\websocket\\_core.py\", line 445, in recv_frame\n    return self.frame_buffer.recv_frame()\n  File \"C:\\Users\\eldoj\\PycharmProjects\\MARK6_V2.0\\.venv\\lib\\site-packages\\websocket\\_abnf.py\", line 338, in recv_frame\n    self.recv_header()\n  File \"C:\\Users\\eldoj\\PycharmProjects\\MARK6_V2.0\\.venv\\lib\\site-packages\\websocket\\_abnf.py\", line 294, in recv_header\n    header = self.recv_strict(2)\n  File \"C:\\Users\\eldoj\\PycharmProjects\\MARK6_V2.0\\.venv\\lib\\site-packages\\websocket\\_abnf.py\", line 373, in recv_strict\n    bytes_ = self.recv(min(16384, shortage))\n  File \"C:\\Users\\eldoj\\PycharmProjects\\MARK6_V2.0\\.venv\\lib\\site-packages\\websocket\\_core.py\", line 529, in _recv\n    return recv(self.sock, bufsize)\n  File \"C:\\Users\\eldoj\\PycharmProjects\\MARK6_V2.0\\.venv\\lib\\site-packages\\websocket\\_socket.py\", line 122, in recv\n    raise WebSocketConnectionClosedException(\nwebsocket._exceptions.WebSocketConnectionClosedException: Connection to remote host was lost.\n\nDuring handling of the above exception, another exception occurred:\n\nTraceback (most recent call last):\n  File \"C:\\Users\\eldoj\\PycharmProjects\\MARK6_V2.0\\.venv\\lib\\site-packages\\urllib3\\connectionpool.py\", line 787, in urlopen\n    response = self._make_request(\n  File \"C:\\Users\\eldoj\\PycharmProjects\\MARK6_V2.0\\.venv\\lib\\site-packages\\urllib3\\connectionpool.py\", line 488, in _make_request\n    raise new_e\n  File \"C:\\Users\\eldoj\\PycharmProjects\\MARK6_V2.0\\.venv\\lib\\site-packages\\urllib3\\connectionpool.py\", line 464, in _make_request\n    self._validate_conn(conn)\n  File \"C:\\Users\\eldoj\\PycharmProjects\\MARK6_V2.0\\.venv\\lib\\site-packages\\urllib3\\connectionpool.py\", line 1093, in _validate_conn\n    conn.connect()\n  File \"C:\\Users\\eldoj\\PycharmProjects\\MARK6_V2.0\\.venv\\lib\\site-packages\\urllib3\\connection.py\", line 741, in connect\n    sock_and_verified = _ssl_wrap_socket_and_match_hostname(\n  File \"C:\\Users\\eldoj\\PycharmProjects\\MARK6_V2.0\\.venv\\lib\\site-packages\\urllib3\\connection.py\", line 920, in _ssl_wrap_socket_and_match_hostname\n    ssl_sock = ssl_wrap_socket(\n  File \"C:\\Users\\eldoj\\PycharmProjects\\MARK6_V2.0\\.venv\\lib\\site-packages\\urllib3\\util\\ssl_.py\", line 480, in ssl_wrap_socket\n    ssl_sock = _ssl_wrap_socket_impl(sock, context, tls_in_tls, server_hostname)\n  File \"C:\\Users\\eldoj\\PycharmProjects\\MARK6_V2.0\\.venv\\lib\\site-packages\\urllib3\\util\\ssl_.py\", line 524, in _ssl_wrap_socket_impl\n    return ssl_context.wrap_socket(sock, server_hostname=server_hostname)\n  File \"C:\\Users\\eldoj\\AppData\\Local\\Programs\\Python\\Python310\\lib\\ssl.py\", line 513, in wrap_socket\n    return self.sslsocket_class._create(\n  File \"C:\\Users\\eldoj\\AppData\\Local\\Programs\\Python\\Python310\\lib\\ssl.py\", line 1071, in _create\n    self.do_handshake()\n  File \"C:\\Users\\eldoj\\AppData\\Local\\Programs\\Python\\Python310\\lib\\ssl.py\", line 1342, in do_handshake\n    self._sslobj.do_handshake()\nConnectionResetError: [WinError 10054] An existing connection was forcibly closed by the remote host\n\nDuring handling of the above exception, another exception occurred:\n\nTraceback (most recent call last):\n  File \"C:\\Users\\eldoj\\PycharmProjects\\MARK6_V2.0\\.venv\\lib\\site-packages\\requests\\adapters.py\", line 486, in send\n    resp = conn.urlopen(\n  File \"C:\\Users\\eldoj\\PycharmProjects\\MARK6_V2.0\\.venv\\lib\\site-packages\\urllib3\\connectionpool.py\", line 841, in urlopen\n    retries = retries.increment(\n  File \"C:\\Users\\eldoj\\PycharmProjects\\MARK6_V2.0\\.venv\\lib\\site-packages\\urllib3\\util\\retry.py\", line 474, in increment\n    raise reraise(type(error), error, _stacktrace)\n  File \"C:\\Users\\eldoj\\PycharmProjects\\MARK6_V2.0\\.venv\\lib\\site-packages\\urllib3\\util\\util.py\", line 38, in reraise\n    raise value.with_traceback(tb)\n  File \"C:\\Users\\eldoj\\PycharmProjects\\MARK6_V2.0\\.venv\\lib\\site-packages\\urllib3\\connectionpool.py\", line 787, in urlopen\n    response = self._make_request(\n  File \"C:\\Users\\eldoj\\PycharmProjects\\MARK6_V2.0\\.venv\\lib\\site-packages\\urllib3\\connectionpool.py\", line 488, in _make_request\n    raise new_e\n  File \"C:\\Users\\eldoj\\PycharmProjects\\MARK6_V2.0\\.venv\\lib\\site-packages\\urllib3\\connectionpool.py\", line 464, in _make_request\n    self._validate_conn(conn)\n  File \"C:\\Users\\eldoj\\PycharmProjects\\MARK6_V2.0\\.venv\\lib\\site-packages\\urllib3\\connectionpool.py\", line 1093, in _validate_conn\n    conn.connect()\n  File \"C:\\Users\\eldoj\\PycharmProjects\\MARK6_V2.0\\.venv\\lib\\site-packages\\urllib3\\connection.py\", line 741, in connect\n    sock_and_verified = _ssl_wrap_socket_and_match_hostname(\n  File \"C:\\Users\\eldoj\\PycharmProjects\\MARK6_V2.0\\.venv\\lib\\site-packages\\urllib3\\connection.py\", line 920, in _ssl_wrap_socket_and_match_hostname\n    ssl_sock = ssl_wrap_socket(\n  File \"C:\\Users\\eldoj\\PycharmProjects\\MARK6_V2.0\\.venv\\lib\\site-packages\\urllib3\\util\\ssl_.py\", line 480, in ssl_wrap_socket\n    ssl_sock = _ssl_wrap_socket_impl(sock, context, tls_in_tls, server_hostname)\n  File \"C:\\Users\\eldoj\\PycharmProjects\\MARK6_V2.0\\.venv\\lib\\site-packages\\urllib3\\util\\ssl_.py\", line 524, in _ssl_wrap_socket_impl\n    return ssl_context.wrap_socket(sock, server_hostname=server_hostname)\n  File \"C:\\Users\\eldoj\\AppData\\Local\\Programs\\Python\\Python310\\lib\\ssl.py\", line 513, in wrap_socket\n    return self.sslsocket_class._create(\n  File \"C:\\Users\\eldoj\\AppData\\Local\\Programs\\Python\\Python310\\lib\\ssl.py\", line 1071, in _create\n    self.do_handshake()\n  File \"C:\\Users\\eldoj\\AppData\\Local\\Programs\\Python\\Python310\\lib\\ssl.py\", line 1342, in do_handshake\n    self._sslobj.do_handshake()\nurllib3.exceptions.ProtocolError: ('Connection aborted.', ConnectionResetError(10054, 'An existing connection was forcibly closed by the remote host', None, 10054, None))\n\nDuring handling of the above exception, another exception occurred:\n\nTraceback (most recent call last):\n  File \"C:\\Users\\eldoj\\PycharmProjects\\MARK6_V2.0\\.venv\\lib\\site-packages\\fyers_apiv3\\FyersWebsocket\\data_ws.py\", line 63, in symbol_to_hsmtoken\n    response = requests.post(\n  File \"C:\\Users\\eldoj\\PycharmProjects\\MARK6_V2.0\\.venv\\lib\\site-packages\\requests\\api.py\", line 115, in post\n    return request(\"post\", url, data=data, json=json, **kwargs)\n  File \"C:\\Users\\eldoj\\PycharmProjects\\MARK6_V2.0\\.venv\\lib\\site-packages\\requests\\api.py\", line 59, in request\n    return session.request(method=method, url=url, **kwargs)\n  File \"C:\\Users\\eldoj\\PycharmProjects\\MARK6_V2.0\\.venv\\lib\\site-packages\\requests\\sessions.py\", line 589, in request\n    resp = self.send(prep, **send_kwargs)\n  File \"C:\\Users\\eldoj\\PycharmProjects\\MARK6_V2.0\\.venv\\lib\\site-packages\\requests\\sessions.py\", line 703, in send\n    r = adapter.send(request, **kwargs)\n  File \"C:\\Users\\eldoj\\PycharmProjects\\MARK6_V2.0\\.venv\\lib\\site-packages\\requests\\adapters.py\", line 501, in send\n    raise ConnectionError(err, request=request)\nrequests.exceptions.ConnectionError: ('Connection aborted.', ConnectionResetError(10054, 'An existing connection was forcibly closed by the remote host', None, 10054, None))","exception_name":"ConnectionError"}
{"level":"ERROR","location":"[exception:108] fyers_logger","message":"'NoneType' object is not subscriptable","timestamp":"2025-06-27 12:53:10,546+0530","service":"FyersDataSocket","exception":"Traceback (most recent call last):\n  File \"C:\\Users\\eldoj\\PycharmProjects\\MARK6_V2.0\\.venv\\lib\\site-packages\\websocket\\_app.py\", line 428, in setSock\n    dispatcher.read(self.sock.sock, read, check)\n  File \"C:\\Users\\eldoj\\PycharmProjects\\MARK6_V2.0\\.venv\\lib\\site-packages\\websocket\\_app.py\", line 99, in read\n    if not read_callback():\n  File \"C:\\Users\\eldoj\\PycharmProjects\\MARK6_V2.0\\.venv\\lib\\site-packages\\websocket\\_app.py\", line 442, in read\n    raise e\n  File \"C:\\Users\\eldoj\\PycharmProjects\\MARK6_V2.0\\.venv\\lib\\site-packages\\websocket\\_app.py\", line 437, in read\n    op_code, frame = self.sock.recv_data_frame(True)\n  File \"C:\\Users\\eldoj\\PycharmProjects\\MARK6_V2.0\\.venv\\lib\\site-packages\\websocket\\_core.py\", line 406, in recv_data_frame\n    frame = self.recv_frame()\n  File \"C:\\Users\\eldoj\\PycharmProjects\\MARK6_V2.0\\.venv\\lib\\site-packages\\websocket\\_core.py\", line 445, in recv_frame\n    return self.frame_buffer.recv_frame()\n  File \"C:\\Users\\eldoj\\PycharmProjects\\MARK6_V2.0\\.venv\\lib\\site-packages\\websocket\\_abnf.py\", line 338, in recv_frame\n    self.recv_header()\n  File \"C:\\Users\\eldoj\\PycharmProjects\\MARK6_V2.0\\.venv\\lib\\site-packages\\websocket\\_abnf.py\", line 294, in recv_header\n    header = self.recv_strict(2)\n  File \"C:\\Users\\eldoj\\PycharmProjects\\MARK6_V2.0\\.venv\\lib\\site-packages\\websocket\\_abnf.py\", line 373, in recv_strict\n    bytes_ = self.recv(min(16384, shortage))\n  File \"C:\\Users\\eldoj\\PycharmProjects\\MARK6_V2.0\\.venv\\lib\\site-packages\\websocket\\_core.py\", line 529, in _recv\n    return recv(self.sock, bufsize)\n  File \"C:\\Users\\eldoj\\PycharmProjects\\MARK6_V2.0\\.venv\\lib\\site-packages\\websocket\\_socket.py\", line 122, in recv\n    raise WebSocketConnectionClosedException(\nwebsocket._exceptions.WebSocketConnectionClosedException: Connection to remote host was lost.\n\nDuring handling of the above exception, another exception occurred:\n\nTraceback (most recent call last):\n  File \"C:\\Users\\eldoj\\PycharmProjects\\MARK6_V2.0\\.venv\\lib\\site-packages\\fyers_apiv3\\FyersWebsocket\\data_ws.py\", line 1333, in __symbol_conversion\n    if symbol_value[3] != \"\":\nTypeError: 'NoneType' object is not subscriptable","exception_name":"TypeError"}
{"level":"ERROR","location":"[<lambda>:1663] data_ws","message":"Connection to remote host was lost.","timestamp":"2025-06-27 12:58:21,182+0530","service":"FyersDataSocket"}
{"level":"ERROR","location":"[exception:108] fyers_logger","message":"('Connection aborted.', ConnectionResetError(10054, 'An existing connection was forcibly closed by the remote host', None, 10054, None))","timestamp":"2025-06-27 12:58:46,465+0530","service":"FyersDataSocket","exception":"Traceback (most recent call last):\n  File \"C:\\Users\\eldoj\\PycharmProjects\\MARK6_V2.0\\.venv\\lib\\site-packages\\websocket\\_app.py\", line 428, in setSock\n    dispatcher.read(self.sock.sock, read, check)\n  File \"C:\\Users\\eldoj\\PycharmProjects\\MARK6_V2.0\\.venv\\lib\\site-packages\\websocket\\_app.py\", line 99, in read\n    if not read_callback():\n  File \"C:\\Users\\eldoj\\PycharmProjects\\MARK6_V2.0\\.venv\\lib\\site-packages\\websocket\\_app.py\", line 442, in read\n    raise e\n  File \"C:\\Users\\eldoj\\PycharmProjects\\MARK6_V2.0\\.venv\\lib\\site-packages\\websocket\\_app.py\", line 437, in read\n    op_code, frame = self.sock.recv_data_frame(True)\n  File \"C:\\Users\\eldoj\\PycharmProjects\\MARK6_V2.0\\.venv\\lib\\site-packages\\websocket\\_core.py\", line 406, in recv_data_frame\n    frame = self.recv_frame()\n  File \"C:\\Users\\eldoj\\PycharmProjects\\MARK6_V2.0\\.venv\\lib\\site-packages\\websocket\\_core.py\", line 445, in recv_frame\n    return self.frame_buffer.recv_frame()\n  File \"C:\\Users\\eldoj\\PycharmProjects\\MARK6_V2.0\\.venv\\lib\\site-packages\\websocket\\_abnf.py\", line 338, in recv_frame\n    self.recv_header()\n  File \"C:\\Users\\eldoj\\PycharmProjects\\MARK6_V2.0\\.venv\\lib\\site-packages\\websocket\\_abnf.py\", line 294, in recv_header\n    header = self.recv_strict(2)\n  File \"C:\\Users\\eldoj\\PycharmProjects\\MARK6_V2.0\\.venv\\lib\\site-packages\\websocket\\_abnf.py\", line 373, in recv_strict\n    bytes_ = self.recv(min(16384, shortage))\n  File \"C:\\Users\\eldoj\\PycharmProjects\\MARK6_V2.0\\.venv\\lib\\site-packages\\websocket\\_core.py\", line 529, in _recv\n    return recv(self.sock, bufsize)\n  File \"C:\\Users\\eldoj\\PycharmProjects\\MARK6_V2.0\\.venv\\lib\\site-packages\\websocket\\_socket.py\", line 122, in recv\n    raise WebSocketConnectionClosedException(\nwebsocket._exceptions.WebSocketConnectionClosedException: Connection to remote host was lost.\n\nDuring handling of the above exception, another exception occurred:\n\nTraceback (most recent call last):\n  File \"C:\\Users\\eldoj\\PycharmProjects\\MARK6_V2.0\\.venv\\lib\\site-packages\\urllib3\\connectionpool.py\", line 787, in urlopen\n    response = self._make_request(\n  File \"C:\\Users\\eldoj\\PycharmProjects\\MARK6_V2.0\\.venv\\lib\\site-packages\\urllib3\\connectionpool.py\", line 488, in _make_request\n    raise new_e\n  File \"C:\\Users\\eldoj\\PycharmProjects\\MARK6_V2.0\\.venv\\lib\\site-packages\\urllib3\\connectionpool.py\", line 464, in _make_request\n    self._validate_conn(conn)\n  File \"C:\\Users\\eldoj\\PycharmProjects\\MARK6_V2.0\\.venv\\lib\\site-packages\\urllib3\\connectionpool.py\", line 1093, in _validate_conn\n    conn.connect()\n  File \"C:\\Users\\eldoj\\PycharmProjects\\MARK6_V2.0\\.venv\\lib\\site-packages\\urllib3\\connection.py\", line 741, in connect\n    sock_and_verified = _ssl_wrap_socket_and_match_hostname(\n  File \"C:\\Users\\eldoj\\PycharmProjects\\MARK6_V2.0\\.venv\\lib\\site-packages\\urllib3\\connection.py\", line 920, in _ssl_wrap_socket_and_match_hostname\n    ssl_sock = ssl_wrap_socket(\n  File \"C:\\Users\\eldoj\\PycharmProjects\\MARK6_V2.0\\.venv\\lib\\site-packages\\urllib3\\util\\ssl_.py\", line 480, in ssl_wrap_socket\n    ssl_sock = _ssl_wrap_socket_impl(sock, context, tls_in_tls, server_hostname)\n  File \"C:\\Users\\eldoj\\PycharmProjects\\MARK6_V2.0\\.venv\\lib\\site-packages\\urllib3\\util\\ssl_.py\", line 524, in _ssl_wrap_socket_impl\n    return ssl_context.wrap_socket(sock, server_hostname=server_hostname)\n  File \"C:\\Users\\eldoj\\AppData\\Local\\Programs\\Python\\Python310\\lib\\ssl.py\", line 513, in wrap_socket\n    return self.sslsocket_class._create(\n  File \"C:\\Users\\eldoj\\AppData\\Local\\Programs\\Python\\Python310\\lib\\ssl.py\", line 1071, in _create\n    self.do_handshake()\n  File \"C:\\Users\\eldoj\\AppData\\Local\\Programs\\Python\\Python310\\lib\\ssl.py\", line 1342, in do_handshake\n    self._sslobj.do_handshake()\nConnectionResetError: [WinError 10054] An existing connection was forcibly closed by the remote host\n\nDuring handling of the above exception, another exception occurred:\n\nTraceback (most recent call last):\n  File \"C:\\Users\\eldoj\\PycharmProjects\\MARK6_V2.0\\.venv\\lib\\site-packages\\requests\\adapters.py\", line 486, in send\n    resp = conn.urlopen(\n  File \"C:\\Users\\eldoj\\PycharmProjects\\MARK6_V2.0\\.venv\\lib\\site-packages\\urllib3\\connectionpool.py\", line 841, in urlopen\n    retries = retries.increment(\n  File \"C:\\Users\\eldoj\\PycharmProjects\\MARK6_V2.0\\.venv\\lib\\site-packages\\urllib3\\util\\retry.py\", line 474, in increment\n    raise reraise(type(error), error, _stacktrace)\n  File \"C:\\Users\\eldoj\\PycharmProjects\\MARK6_V2.0\\.venv\\lib\\site-packages\\urllib3\\util\\util.py\", line 38, in reraise\n    raise value.with_traceback(tb)\n  File \"C:\\Users\\eldoj\\PycharmProjects\\MARK6_V2.0\\.venv\\lib\\site-packages\\urllib3\\connectionpool.py\", line 787, in urlopen\n    response = self._make_request(\n  File \"C:\\Users\\eldoj\\PycharmProjects\\MARK6_V2.0\\.venv\\lib\\site-packages\\urllib3\\connectionpool.py\", line 488, in _make_request\n    raise new_e\n  File \"C:\\Users\\eldoj\\PycharmProjects\\MARK6_V2.0\\.venv\\lib\\site-packages\\urllib3\\connectionpool.py\", line 464, in _make_request\n    self._validate_conn(conn)\n  File \"C:\\Users\\eldoj\\PycharmProjects\\MARK6_V2.0\\.venv\\lib\\site-packages\\urllib3\\connectionpool.py\", line 1093, in _validate_conn\n    conn.connect()\n  File \"C:\\Users\\eldoj\\PycharmProjects\\MARK6_V2.0\\.venv\\lib\\site-packages\\urllib3\\connection.py\", line 741, in connect\n    sock_and_verified = _ssl_wrap_socket_and_match_hostname(\n  File \"C:\\Users\\eldoj\\PycharmProjects\\MARK6_V2.0\\.venv\\lib\\site-packages\\urllib3\\connection.py\", line 920, in _ssl_wrap_socket_and_match_hostname\n    ssl_sock = ssl_wrap_socket(\n  File \"C:\\Users\\eldoj\\PycharmProjects\\MARK6_V2.0\\.venv\\lib\\site-packages\\urllib3\\util\\ssl_.py\", line 480, in ssl_wrap_socket\n    ssl_sock = _ssl_wrap_socket_impl(sock, context, tls_in_tls, server_hostname)\n  File \"C:\\Users\\eldoj\\PycharmProjects\\MARK6_V2.0\\.venv\\lib\\site-packages\\urllib3\\util\\ssl_.py\", line 524, in _ssl_wrap_socket_impl\n    return ssl_context.wrap_socket(sock, server_hostname=server_hostname)\n  File \"C:\\Users\\eldoj\\AppData\\Local\\Programs\\Python\\Python310\\lib\\ssl.py\", line 513, in wrap_socket\n    return self.sslsocket_class._create(\n  File \"C:\\Users\\eldoj\\AppData\\Local\\Programs\\Python\\Python310\\lib\\ssl.py\", line 1071, in _create\n    self.do_handshake()\n  File \"C:\\Users\\eldoj\\AppData\\Local\\Programs\\Python\\Python310\\lib\\ssl.py\", line 1342, in do_handshake\n    self._sslobj.do_handshake()\nurllib3.exceptions.ProtocolError: ('Connection aborted.', ConnectionResetError(10054, 'An existing connection was forcibly closed by the remote host', None, 10054, None))\n\nDuring handling of the above exception, another exception occurred:\n\nTraceback (most recent call last):\n  File \"C:\\Users\\eldoj\\PycharmProjects\\MARK6_V2.0\\.venv\\lib\\site-packages\\fyers_apiv3\\FyersWebsocket\\data_ws.py\", line 63, in symbol_to_hsmtoken\n    response = requests.post(\n  File \"C:\\Users\\eldoj\\PycharmProjects\\MARK6_V2.0\\.venv\\lib\\site-packages\\requests\\api.py\", line 115, in post\n    return request(\"post\", url, data=data, json=json, **kwargs)\n  File \"C:\\Users\\eldoj\\PycharmProjects\\MARK6_V2.0\\.venv\\lib\\site-packages\\requests\\api.py\", line 59, in request\n    return session.request(method=method, url=url, **kwargs)\n  File \"C:\\Users\\eldoj\\PycharmProjects\\MARK6_V2.0\\.venv\\lib\\site-packages\\requests\\sessions.py\", line 589, in request\n    resp = self.send(prep, **send_kwargs)\n  File \"C:\\Users\\eldoj\\PycharmProjects\\MARK6_V2.0\\.venv\\lib\\site-packages\\requests\\sessions.py\", line 703, in send\n    r = adapter.send(request, **kwargs)\n  File \"C:\\Users\\eldoj\\PycharmProjects\\MARK6_V2.0\\.venv\\lib\\site-packages\\requests\\adapters.py\", line 501, in send\n    raise ConnectionError(err, request=request)\nrequests.exceptions.ConnectionError: ('Connection aborted.', ConnectionResetError(10054, 'An existing connection was forcibly closed by the remote host', None, 10054, None))","exception_name":"ConnectionError"}
{"level":"ERROR","location":"[exception:108] fyers_logger","message":"'NoneType' object is not subscriptable","timestamp":"2025-06-27 12:58:46,470+0530","service":"FyersDataSocket","exception":"Traceback (most recent call last):\n  File \"C:\\Users\\eldoj\\PycharmProjects\\MARK6_V2.0\\.venv\\lib\\site-packages\\websocket\\_app.py\", line 428, in setSock\n    dispatcher.read(self.sock.sock, read, check)\n  File \"C:\\Users\\eldoj\\PycharmProjects\\MARK6_V2.0\\.venv\\lib\\site-packages\\websocket\\_app.py\", line 99, in read\n    if not read_callback():\n  File \"C:\\Users\\eldoj\\PycharmProjects\\MARK6_V2.0\\.venv\\lib\\site-packages\\websocket\\_app.py\", line 442, in read\n    raise e\n  File \"C:\\Users\\eldoj\\PycharmProjects\\MARK6_V2.0\\.venv\\lib\\site-packages\\websocket\\_app.py\", line 437, in read\n    op_code, frame = self.sock.recv_data_frame(True)\n  File \"C:\\Users\\eldoj\\PycharmProjects\\MARK6_V2.0\\.venv\\lib\\site-packages\\websocket\\_core.py\", line 406, in recv_data_frame\n    frame = self.recv_frame()\n  File \"C:\\Users\\eldoj\\PycharmProjects\\MARK6_V2.0\\.venv\\lib\\site-packages\\websocket\\_core.py\", line 445, in recv_frame\n    return self.frame_buffer.recv_frame()\n  File \"C:\\Users\\eldoj\\PycharmProjects\\MARK6_V2.0\\.venv\\lib\\site-packages\\websocket\\_abnf.py\", line 338, in recv_frame\n    self.recv_header()\n  File \"C:\\Users\\eldoj\\PycharmProjects\\MARK6_V2.0\\.venv\\lib\\site-packages\\websocket\\_abnf.py\", line 294, in recv_header\n    header = self.recv_strict(2)\n  File \"C:\\Users\\eldoj\\PycharmProjects\\MARK6_V2.0\\.venv\\lib\\site-packages\\websocket\\_abnf.py\", line 373, in recv_strict\n    bytes_ = self.recv(min(16384, shortage))\n  File \"C:\\Users\\eldoj\\PycharmProjects\\MARK6_V2.0\\.venv\\lib\\site-packages\\websocket\\_core.py\", line 529, in _recv\n    return recv(self.sock, bufsize)\n  File \"C:\\Users\\eldoj\\PycharmProjects\\MARK6_V2.0\\.venv\\lib\\site-packages\\websocket\\_socket.py\", line 122, in recv\n    raise WebSocketConnectionClosedException(\nwebsocket._exceptions.WebSocketConnectionClosedException: Connection to remote host was lost.\n\nDuring handling of the above exception, another exception occurred:\n\nTraceback (most recent call last):\n  File \"C:\\Users\\eldoj\\PycharmProjects\\MARK6_V2.0\\.venv\\lib\\site-packages\\fyers_apiv3\\FyersWebsocket\\data_ws.py\", line 1333, in __symbol_conversion\n    if symbol_value[3] != \"\":\nTypeError: 'NoneType' object is not subscriptable","exception_name":"TypeError"}
{"level":"ERROR","location":"[<lambda>:1663] data_ws","message":"[WinError 10054] An existing connection was forcibly closed by the remote host","timestamp":"2025-06-27 12:59:03,507+0530","service":"FyersDataSocket"}
{"level":"ERROR","location":"[<lambda>:1663] data_ws","message":"Connection to remote host was lost.","timestamp":"2025-06-27 13:50:52,880+0530","service":"FyersDataSocket"}
{"level":"ERROR","location":"[<lambda>:1663] data_ws","message":"Connection to remote host was lost.","timestamp":"2025-06-27 14:21:23,823+0530","service":"FyersDataSocket"}
{"level":"ERROR","location":"[<lambda>:1663] data_ws","message":"Connection to remote host was lost.","timestamp":"2025-06-27 14:23:32,143+0530","service":"FyersDataSocket"}
